HTTP/1.1 200 OK
Transfer-Encoding: chunked
Access-Control-Allow-Origin: *
Access-Control-Expose-Headers: ETag, Link, Location, Retry-After, X-GitHub-OTP, X-RateLimit-Limit, X-RateLimit-Remaining, X-RateLimit-Used, X-RateLimit-Reset, X-OAuth-Scopes, X-Accepted-OAuth-Scopes, X-Poll-Interval, X-GitHub-Media-Type, Deprecation, Sunset
Cache-Control: no-cache
Content-Security-Policy: default-src 'none'
Content-Type: application/json; charset=utf-8
Date: Sat, 14 Nov 2020 18:05:57 GMT
Link: <https://api.github.com/search/issues?q=https%3A%2F%2Fgithub.com%2Fweb2py%2Fweb2py+type%3Aissue+state%3Aclosed&page=2>; rel="next", <https://api.github.com/search/issues?q=https%3A%2F%2Fgithub.com%2Fweb2py%2Fweb2py+type%3Aissue+state%3Aclosed&page=16>; rel="last"
Referrer-Policy: origin-when-cross-origin, strict-origin-when-cross-origin
Server: GitHub.com
Status: 200 OK
Strict-Transport-Security: max-age=31536000; includeSubdomains; preload
Vary: Accept, Authorization, Cookie, X-GitHub-OTP
Vary: Accept-Encoding, Accept, X-Requested-With
Vary: Accept-Encoding
X-Accepted-Oauth-Scopes: 
X-Content-Type-Options: nosniff
X-Frame-Options: deny
X-Github-Media-Type: github.v3; format=json
X-Github-Request-Id: CFA7:13F4:3D25DD7:467B8ED:5FB01C85
X-Oauth-Scopes: repo
X-Ratelimit-Limit: 30
X-Ratelimit-Remaining: 16
X-Ratelimit-Reset: 1605377196
X-Ratelimit-Used: 14
X-Xss-Protection: 1; mode=block

1d18b
{"total_count":477,"incomplete_results":false,"items":[{"url":"https://api.github.com/repos/web2py/py4web/issues/327","repository_url":"https://api.github.com/repos/web2py/py4web","labels_url":"https://api.github.com/repos/web2py/py4web/issues/327/labels{/name}","comments_url":"https://api.github.com/repos/web2py/py4web/issues/327/comments","events_url":"https://api.github.com/repos/web2py/py4web/issues/327/events","html_url":"https://github.com/web2py/py4web/issues/327","id":733669088,"node_id":"MDU6SXNzdWU3MzM2NjkwODg=","number":327,"title":"Runtime error 'This event loop is already running' with --watch, Tornado and Win ","user":{"login":"nicozanf","id":2276743,"node_id":"MDQ6VXNlcjIyNzY3NDM=","avatar_url":"https://avatars1.githubusercontent.com/u/2276743?v=4","gravatar_id":"","url":"https://api.github.com/users/nicozanf","html_url":"https://github.com/nicozanf","followers_url":"https://api.github.com/users/nicozanf/followers","following_url":"https://api.github.com/users/nicozanf/following{/other_user}","gists_url":"https://api.github.com/users/nicozanf/gists{/gist_id}","starred_url":"https://api.github.com/users/nicozanf/starred{/owner}{/repo}","subscriptions_url":"https://api.github.com/users/nicozanf/subscriptions","organizations_url":"https://api.github.com/users/nicozanf/orgs","repos_url":"https://api.github.com/users/nicozanf/repos","events_url":"https://api.github.com/users/nicozanf/events{/privacy}","received_events_url":"https://api.github.com/users/nicozanf/received_events","type":"User","site_admin":false},"labels":[],"state":"closed","locked":false,"assignee":null,"assignees":[],"milestone":null,"comments":1,"created_at":"2020-10-31T08:37:23Z","updated_at":"2020-11-14T04:23:19Z","closed_at":"2020-11-14T04:23:19Z","author_association":"CONTRIBUTOR","active_lock_reason":null,"body":"As reported on [this thread](https://groups.google.com/d/msgid/py4web/ae9c4280-80d5-419a-8a15-07fb87f3c160n%40googlegroups.com?utm_medium=email&utm_source=footer), there is this error:\r\n\r\n```\r\n    raise RuntimeError('This event loop is already running')\r\nRuntimeError: This event loop is already running\r\n```\r\n\r\nrunning py4web on Windows with Tornado (which is the current default web server) and the --watch command switch, both using lazy and sync values.\r\nReplacing Tornado with gevent resolves the problem.","performed_via_github_app":null,"score":1.0},{"url":"https://api.github.com/repos/web2py/py4web/issues/314","repository_url":"https://api.github.com/repos/web2py/py4web","labels_url":"https://api.github.com/repos/web2py/py4web/issues/314/labels{/name}","comments_url":"https://api.github.com/repos/web2py/py4web/issues/314/comments","events_url":"https://api.github.com/repos/web2py/py4web/issues/314/events","html_url":"https://github.com/web2py/py4web/issues/314","id":722302740,"node_id":"MDU6SXNzdWU3MjIzMDI3NDA=","number":314,"title":"sessions expires, but it's not cleared","user":{"login":"misl6","id":8177736,"node_id":"MDQ6VXNlcjgxNzc3MzY=","avatar_url":"https://avatars0.githubusercontent.com/u/8177736?v=4","gravatar_id":"","url":"https://api.github.com/users/misl6","html_url":"https://github.com/misl6","followers_url":"https://api.github.com/users/misl6/followers","following_url":"https://api.github.com/users/misl6/following{/other_user}","gists_url":"https://api.github.com/users/misl6/gists{/gist_id}","starred_url":"https://api.github.com/users/misl6/starred{/owner}{/repo}","subscriptions_url":"https://api.github.com/users/misl6/subscriptions","organizations_url":"https://api.github.com/users/misl6/orgs","repos_url":"https://api.github.com/users/misl6/repos","events_url":"https://api.github.com/users/misl6/events{/privacy}","received_events_url":"https://api.github.com/users/misl6/received_events","type":"User","site_admin":false},"labels":[],"state":"closed","locked":false,"assignee":null,"assignees":[],"milestone":null,"comments":0,"created_at":"2020-10-15T12:46:17Z","updated_at":"2020-10-18T02:34:41Z","closed_at":"2020-10-18T02:34:41Z","author_association":"CONTRIBUTOR","active_lock_reason":null,"body":"When calling a login protected api, such as `/auth/api/profile`, the session expiration is checked and a 403 is raised if the session is expired.\r\nhttps://github.com/web2py/py4web/blob/f15ef356d37af68d61feeae34cb856f81f426584/py4web/utils/auth.py#L91\r\n\r\nBut, `auth.is_logged_in` it still returns `True`, cause the session it's not cleared on expiration.","performed_via_github_app":null,"score":1.0},{"url":"https://api.github.com/repos/IdentityPython/pysaml2/issues/237","repository_url":"https://api.github.com/repos/IdentityPython/pysaml2","labels_url":"https://api.github.com/repos/IdentityPython/pysaml2/issues/237/labels{/name}","comments_url":"https://api.github.com/repos/IdentityPython/pysaml2/issues/237/comments","events_url":"https://api.github.com/repos/IdentityPython/pysaml2/issues/237/events","html_url":"https://github.com/IdentityPython/pysaml2/issues/237","id":93830193,"node_id":"MDU6SXNzdWU5MzgzMDE5Mw==","number":237,"title":"Example appears not working","user":{"login":"josedesoto","id":1744837,"node_id":"MDQ6VXNlcjE3NDQ4Mzc=","avatar_url":"https://avatars1.githubusercontent.com/u/1744837?v=4","gravatar_id":"","url":"https://api.github.com/users/josedesoto","html_url":"https://github.com/josedesoto","followers_url":"https://api.github.com/users/josedesoto/followers","following_url":"https://api.github.com/users/josedesoto/following{/other_user}","gists_url":"https://api.github.com/users/josedesoto/gists{/gist_id}","starred_url":"https://api.github.com/users/josedesoto/starred{/owner}{/repo}","subscriptions_url":"https://api.github.com/users/josedesoto/subscriptions","organizations_url":"https://api.github.com/users/josedesoto/orgs","repos_url":"https://api.github.com/users/josedesoto/repos","events_url":"https://api.github.com/users/josedesoto/events{/privacy}","received_events_url":"https://api.github.com/users/josedesoto/received_events","type":"User","site_admin":false},"labels":[],"state":"closed","locked":false,"assignee":null,"assignees":[],"milestone":null,"comments":3,"created_at":"2015-07-08T16:13:55Z","updated_at":"2020-09-05T19:32:32Z","closed_at":"2020-09-05T19:32:31Z","author_association":"NONE","active_lock_reason":null,"body":"After install everything and pass all the tests, I am trying to see how the examples works:\n- example/idp2\n- example/sp-wsgi\n\nI have run the command `./all.sh start` and everything looks fine. No errors are displayed and the IDP is running in the port 8088 and the SP in 8087. After run the URL: _http://localhost:8087_ I can see how the SP redirects to the IDP where the browser display the form to introduce the user and the password. In this step _idp.log_ shows the next errors:\n\n```\n2015-07-08 17:11:09,640 saml2.sigver:DEBUG ==== Certs from metadata ==== None: [(<open file '<fdopen>', mode 'w+b' at 0x7f7967a62c90>, '/tmp/tmpfbbwV7.pem')] ====\n2015-07-08 17:11:09,641 saml2.sigver:DEBUG xmlsec command: /usr/bin/xmlsec1 --verify --pubkey-cert-pem /tmp/tmpfbbwV7.pem --id-attr:ID urn:oasis:names:tc:SAML:2.0:protocol:AuthnRequest --store-signatures --node-id id-FITgiINxgEWzl5TRL --output /tmp/tmpBCbfkU.xml /tmp/tmpIo395A.xml\n2015-07-08 17:11:09,678 saml2.sigver:ERROR\n....\n/tmp/tmpIo395A.xml:1: parser error : Start tag expected, '<' not found\nnVZZk6o4FH6/v8LiPlrdBNR2qWtPhVXUoGDE5Q0xLApECYj664fW22v13JqZx/PlrN85Ocmvv85JXDuR\n^\nError: failed to parse xml file \"/tmp/tmpIo395A.xml\"\nError: failed to load document \"/tmp/tmpIo395A.xml\"\nERROR\nSignedInfo References (ok/all): 0/0\nManifests References (ok/all): 0/0\nError: failed to verify file \"/tmp/tmpIo395A.xml\n```\n\nNote: The IDP does not create any of the _/tmp/..._ files.\n\nWhen I introduce the user and the password, for example: roland / dianakra  the IDP display the next exceptions:\n\n```\n127.0.0.1 - - [08/Jul/2015 17:14:52] \"POST /verify HTTP/1.1\" 302 438\n127.0.0.1 - - [08/Jul/2015 17:14:52] \"GET /sso/redirect?id=HavNriDUIVxIm0fTmnXwZx9D&key=bc7f78d00f608903e9f825593bbbff32298aba12 HTTP/1.1\" 200 47\nTraceback (most recent call last):\n  File \"/usr/lib/python2.7/wsgiref/handlers.py\", line 86, in run\n    self.finish_response()\n  File \"/usr/lib/python2.7/wsgiref/handlers.py\", line 128, in finish_response\n    self.write(data)\n  File \"/usr/lib/python2.7/wsgiref/handlers.py\", line 204, in write\n    assert type(data) is StringType,\"write() argument must be string\"\nAssertionError: write() argument must be string\n127.0.0.1 - - [08/Jul/2015 17:14:52] \"GET /sso/redirect?id=HavNriDUIVxIm0fTmnXwZx9D&key=bc7f78d00f608903e9f825593bbbff32298aba12 HTTP/1.1\" 500 59\n----------------------------------------\nException happened during processing of request from ('127.0.0.1', 59521)\nTraceback (most recent call last):\n  File \"/usr/lib/python2.7/SocketServer.py\", line 295, in _handle_request_noblock\n    self.process_request(request, client_address)\n  File \"/usr/lib/python2.7/SocketServer.py\", line 321, in process_request\n    self.finish_request(request, client_address)\n  File \"/usr/lib/python2.7/SocketServer.py\", line 334, in finish_request\n    self.RequestHandlerClass(request, client_address, self)\n  File \"/usr/lib/python2.7/SocketServer.py\", line 655, in __init__\n    self.handle()\n  File \"/usr/lib/python2.7/wsgiref/simple_server.py\", line 131, in handle\n    handler.run(self.server.get_app())\n  File \"/usr/lib/python2.7/wsgiref/handlers.py\", line 92, in run\n    self.close()\n  File \"/usr/lib/python2.7/wsgiref/simple_server.py\", line 33, in close\n    self.status.split(' ',1)[0], self.bytes_sent\nAttributeError: 'NoneType' object has no attribute 'split'\n```\n\nDoes anyone has the same problem?\nUsing Ubuntu 15.04 with Python 2.7\n","performed_via_github_app":null,"score":1.0},{"url":"https://api.github.com/repos/web2py/py4web/issues/175","repository_url":"https://api.github.com/repos/web2py/py4web","labels_url":"https://api.github.com/repos/web2py/py4web/issues/175/labels{/name}","comments_url":"https://api.github.com/repos/web2py/py4web/issues/175/comments","events_url":"https://api.github.com/repos/web2py/py4web/issues/175/events","html_url":"https://github.com/web2py/py4web/issues/175","id":611510096,"node_id":"MDU6SXNzdWU2MTE1MTAwOTY=","number":175,"title":"strange file in _scaffold","user":{"login":"lucadealfaro","id":118022,"node_id":"MDQ6VXNlcjExODAyMg==","avatar_url":"https://avatars0.githubusercontent.com/u/118022?v=4","gravatar_id":"","url":"https://api.github.com/users/lucadealfaro","html_url":"https://github.com/lucadealfaro","followers_url":"https://api.github.com/users/lucadealfaro/followers","following_url":"https://api.github.com/users/lucadealfaro/following{/other_user}","gists_url":"https://api.github.com/users/lucadealfaro/gists{/gist_id}","starred_url":"https://api.github.com/users/lucadealfaro/starred{/owner}{/repo}","subscriptions_url":"https://api.github.com/users/lucadealfaro/subscriptions","organizations_url":"https://api.github.com/users/lucadealfaro/orgs","repos_url":"https://api.github.com/users/lucadealfaro/repos","events_url":"https://api.github.com/users/lucadealfaro/events{/privacy}","received_events_url":"https://api.github.com/users/lucadealfaro/received_events","type":"User","site_admin":false},"labels":[],"state":"closed","locked":false,"assignee":null,"assignees":[],"milestone":null,"comments":1,"created_at":"2020-05-03T21:19:07Z","updated_at":"2020-07-26T21:36:51Z","closed_at":"2020-07-26T21:36:51Z","author_association":"CONTRIBUTOR","active_lock_reason":null,"body":"I think this is there by mistake: https://github.com/web2py/py4web/blob/master/apps/_scaffold/celerybeat-schedule.db","performed_via_github_app":null,"score":1.0},{"url":"https://api.github.com/repos/web2py/pydal/issues/620","repository_url":"https://api.github.com/repos/web2py/pydal","labels_url":"https://api.github.com/repos/web2py/pydal/issues/620/labels{/name}","comments_url":"https://api.github.com/repos/web2py/pydal/issues/620/comments","events_url":"https://api.github.com/repos/web2py/pydal/issues/620/events","html_url":"https://github.com/web2py/pydal/issues/620","id":595092777,"node_id":"MDU6SXNzdWU1OTUwOTI3Nzc=","number":620,"title":"Multiple URIs broken","user":{"login":"timnyborg","id":10194397,"node_id":"MDQ6VXNlcjEwMTk0Mzk3","avatar_url":"https://avatars1.githubusercontent.com/u/10194397?v=4","gravatar_id":"","url":"https://api.github.com/users/timnyborg","html_url":"https://github.com/timnyborg","followers_url":"https://api.github.com/users/timnyborg/followers","following_url":"https://api.github.com/users/timnyborg/following{/other_user}","gists_url":"https://api.github.com/users/timnyborg/gists{/gist_id}","starred_url":"https://api.github.com/users/timnyborg/starred{/owner}{/repo}","subscriptions_url":"https://api.github.com/users/timnyborg/subscriptions","organizations_url":"https://api.github.com/users/timnyborg/orgs","repos_url":"https://api.github.com/users/timnyborg/repos","events_url":"https://api.github.com/users/timnyborg/events{/privacy}","received_events_url":"https://api.github.com/users/timnyborg/received_events","type":"User","site_admin":false},"labels":[],"state":"closed","locked":false,"assignee":null,"assignees":[],"milestone":null,"comments":3,"created_at":"2020-04-06T12:55:55Z","updated_at":"2020-08-04T15:42:24Z","closed_at":"2020-08-04T15:42:24Z","author_association":"CONTRIBUTOR","active_lock_reason":null,"body":"Now that DAL connections only initialize on their first use, the DAL never tries the second URI in a list/tuple if the first fails.  Instead, it just errors out.\r\n\r\nPresumably, this is because the error checking was done in the loop at:\r\nhttps://github.com/web2py/pydal/blob/master/pydal/base.py#L485\r\n\r\nFor each URI, a connection was attempted.  But now, because no connection occurs there, no error can occur there to trigger an attempt on the next URI.  It assumes the first URI is fine, even if it isn't, and passes it to the adapter.","performed_via_github_app":null,"score":1.0},{"url":"https://api.github.com/repos/CoolProp/CoolProp/issues/1078","repository_url":"https://api.github.com/repos/CoolProp/CoolProp","labels_url":"https://api.github.com/repos/CoolProp/CoolProp/issues/1078/labels{/name}","comments_url":"https://api.github.com/repos/CoolProp/CoolProp/issues/1078/comments","events_url":"https://api.github.com/repos/CoolProp/CoolProp/issues/1078/events","html_url":"https://github.com/CoolProp/CoolProp/issues/1078","id":155955318,"node_id":"MDU6SXNzdWUxNTU5NTUzMTg=","number":1078,"title":"CoolProp Online down","user":{"login":"bilderbuchi","id":327442,"node_id":"MDQ6VXNlcjMyNzQ0Mg==","avatar_url":"https://avatars2.githubusercontent.com/u/327442?v=4","gravatar_id":"","url":"https://api.github.com/users/bilderbuchi","html_url":"https://github.com/bilderbuchi","followers_url":"https://api.github.com/users/bilderbuchi/followers","following_url":"https://api.github.com/users/bilderbuchi/following{/other_user}","gists_url":"https://api.github.com/users/bilderbuchi/gists{/gist_id}","starred_url":"https://api.github.com/users/bilderbuchi/starred{/owner}{/repo}","subscriptions_url":"https://api.github.com/users/bilderbuchi/subscriptions","organizations_url":"https://api.github.com/users/bilderbuchi/orgs","repos_url":"https://api.github.com/users/bilderbuchi/repos","events_url":"https://api.github.com/users/bilderbuchi/events{/privacy}","received_events_url":"https://api.github.com/users/bilderbuchi/received_events","type":"User","site_admin":false},"labels":[],"state":"closed","locked":false,"assignee":null,"assignees":[],"milestone":{"url":"https://api.github.com/repos/CoolProp/CoolProp/milestones/14","html_url":"https://github.com/CoolProp/CoolProp/milestone/14","labels_url":"https://api.github.com/repos/CoolProp/CoolProp/milestones/14/labels","id":1781005,"node_id":"MDk6TWlsZXN0b25lMTc4MTAwNQ==","number":14,"title":"v6.1","description":"Patch with minor changes","creator":{"login":"ibell","id":1859947,"node_id":"MDQ6VXNlcjE4NTk5NDc=","avatar_url":"https://avatars2.githubusercontent.com/u/1859947?v=4","gravatar_id":"","url":"https://api.github.com/users/ibell","html_url":"https://github.com/ibell","followers_url":"https://api.github.com/users/ibell/followers","following_url":"https://api.github.com/users/ibell/following{/other_user}","gists_url":"https://api.github.com/users/ibell/gists{/gist_id}","starred_url":"https://api.github.com/users/ibell/starred{/owner}{/repo}","subscriptions_url":"https://api.github.com/users/ibell/subscriptions","organizations_url":"https://api.github.com/users/ibell/orgs","repos_url":"https://api.github.com/users/ibell/repos","events_url":"https://api.github.com/users/ibell/events{/privacy}","received_events_url":"https://api.github.com/users/ibell/received_events","type":"User","site_admin":false},"open_issues":0,"closed_issues":135,"state":"closed","created_at":"2016-05-22T10:55:15Z","updated_at":"2017-11-28T07:48:00Z","due_on":null,"closed_at":"2017-11-28T07:48:00Z"},"comments":13,"created_at":"2016-05-20T12:46:52Z","updated_at":"2020-08-14T06:00:58Z","closed_at":"2016-09-21T02:15:55Z","author_association":"CONTRIBUTOR","active_lock_reason":null,"body":"Coolprop Online at http://ibell.pythonanywhere.com/ has been \"temporarily down for maintenance\" for quite some time (the [page in the docs](http://coolprop.sourceforge.net/online/index.html) asks users to report any problems).\n","performed_via_github_app":null,"score":1.0},{"url":"https://api.github.com/repos/web2py/web2py/issues/1988","repository_url":"https://api.github.com/repos/web2py/web2py","labels_url":"https://api.github.com/repos/web2py/web2py/issues/1988/labels{/name}","comments_url":"https://api.github.com/repos/web2py/web2py/issues/1988/comments","events_url":"https://api.github.com/repos/web2py/web2py/issues/1988/events","html_url":"https://github.com/web2py/web2py/issues/1988","id":350921721,"node_id":"MDU6SXNzdWUzNTA5MjE3MjE=","number":1988,"title":"auth.profile stopped working with email widget in 2.17.1","user":{"login":"amerikan","id":179356,"node_id":"MDQ6VXNlcjE3OTM1Ng==","avatar_url":"https://avatars1.githubusercontent.com/u/179356?v=4","gravatar_id":"","url":"https://api.github.com/users/amerikan","html_url":"https://github.com/amerikan","followers_url":"https://api.github.com/users/amerikan/followers","following_url":"https://api.github.com/users/amerikan/following{/other_user}","gists_url":"https://api.github.com/users/amerikan/gists{/gist_id}","starred_url":"https://api.github.com/users/amerikan/starred{/owner}{/repo}","subscriptions_url":"https://api.github.com/users/amerikan/subscriptions","organizations_url":"https://api.github.com/users/amerikan/orgs","repos_url":"https://api.github.com/users/amerikan/repos","events_url":"https://api.github.com/users/amerikan/events{/privacy}","received_events_url":"https://api.github.com/users/amerikan/received_events","type":"User","site_admin":false},"labels":[],"state":"closed","locked":false,"assignee":null,"assignees":[],"milestone":null,"comments":2,"created_at":"2018-08-15T18:47:08Z","updated_at":"2020-08-02T16:39:23Z","closed_at":"2020-08-02T16:39:23Z","author_association":"CONTRIBUTOR","active_lock_reason":null,"body":"After upgrading, a part of my website doesn't work anymore. Here's the situation:\r\n\r\n**Controller**\r\n```python\r\nbasic_form = auth.profile(next=URL('default', 'user/account', host=True, scheme=True))\r\n\r\nreturn dict(basic_form=basic_form)\r\n```\r\n\r\n**View**\r\n```html\r\n{{basic_form.custom.widget.email['_class'] = 'form-control'}}\r\n{{basic_form.custom.widget.email['_readonly'] = 'readonly'}}\r\n{{basic_form.custom.widget.email['_style'] = 'display:none;'}}\r\n{{basic_form.custom.widget.email}}\r\n```\r\n\r\n**Error**\r\n<type 'exceptions.TypeError'>('str' object does not support item assignment)\r\n\r\nI print out `basic_form` to see what it was returning and it seems it no longer has email input in it anymore. I think that's why when I try to assign something to email widget it throws that error. Was there some change that cause this?","performed_via_github_app":null,"score":1.0},{"url":"https://api.github.com/repos/hashicorp/vagrant/issues/11856","repository_url":"https://api.github.com/repos/hashicorp/vagrant","labels_url":"https://api.github.com/repos/hashicorp/vagrant/issues/11856/labels{/name}","comments_url":"https://api.github.com/repos/hashicorp/vagrant/issues/11856/comments","events_url":"https://api.github.com/repos/hashicorp/vagrant/issues/11856/events","html_url":"https://github.com/hashicorp/vagrant/issues/11856","id":686910179,"node_id":"MDU6SXNzdWU2ODY5MTAxNzk=","number":11856,"title":"Strange error after 2.2.9 -> 2.2.10","user":{"login":"dburba","id":6642423,"node_id":"MDQ6VXNlcjY2NDI0MjM=","avatar_url":"https://avatars2.githubusercontent.com/u/6642423?v=4","gravatar_id":"","url":"https://api.github.com/users/dburba","html_url":"https://github.com/dburba","followers_url":"https://api.github.com/users/dburba/followers","following_url":"https://api.github.com/users/dburba/following{/other_user}","gists_url":"https://api.github.com/users/dburba/gists{/gist_id}","starred_url":"https://api.github.com/users/dburba/starred{/owner}{/repo}","subscriptions_url":"https://api.github.com/users/dburba/subscriptions","organizations_url":"https://api.github.com/users/dburba/orgs","repos_url":"https://api.github.com/users/dburba/repos","events_url":"https://api.github.com/users/dburba/events{/privacy}","received_events_url":"https://api.github.com/users/dburba/received_events","type":"User","site_admin":false},"labels":[{"id":25816,"node_id":"MDU6TGFiZWwyNTgxNg==","url":"https://api.github.com/repos/hashicorp/vagrant/labels/bug","name":"bug","color":"e11d21","default":true,"description":null}],"state":"closed","locked":true,"assignee":null,"assignees":[],"milestone":{"url":"https://api.github.com/repos/hashicorp/vagrant/milestones/48","html_url":"https://github.com/hashicorp/vagrant/milestone/48","labels_url":"https://api.github.com/repos/hashicorp/vagrant/milestones/48/labels","id":5808447,"node_id":"MDk6TWlsZXN0b25lNTgwODQ0Nw==","number":48,"title":"2.2.11","description":"","creator":{"login":"soapy1","id":976973,"node_id":"MDQ6VXNlcjk3Njk3Mw==","avatar_url":"https://avatars0.githubusercontent.com/u/976973?v=4","gravatar_id":"","url":"https://api.github.com/users/soapy1","html_url":"https://github.com/soapy1","followers_url":"https://api.github.com/users/soapy1/followers","following_url":"https://api.github.com/users/soapy1/following{/other_user}","gists_url":"https://api.github.com/users/soapy1/gists{/gist_id}","starred_url":"https://api.github.com/users/soapy1/starred{/owner}{/repo}","subscriptions_url":"https://api.github.com/users/soapy1/subscriptions","organizations_url":"https://api.github.com/users/soapy1/orgs","repos_url":"https://api.github.com/users/soapy1/repos","events_url":"https://api.github.com/users/soapy1/events{/privacy}","received_events_url":"https://api.github.com/users/soapy1/received_events","type":"User","site_admin":false},"open_issues":15,"closed_issues":7,"state":"open","created_at":"2020-08-25T16:06:34Z","updated_at":"2020-10-28T22:41:26Z","due_on":null,"closed_at":null},"comments":5,"created_at":"2020-08-27T03:30:46Z","updated_at":"2020-10-16T01:50:15Z","closed_at":"2020-09-15T20:47:36Z","author_association":"NONE","active_lock_reason":"resolved","body":"After updating to v2.2.10 I get error on vagrant up:\r\n\r\n```\r\nTraceback (most recent call last):\r\n\t17: from /opt/vagrant/embedded/gems/2.2.10/gems/vagrant-2.2.10/bin/vagrant:205:in `<main>'\r\n\t16: from /opt/vagrant/embedded/gems/2.2.10/gems/vagrant-2.2.10/lib/vagrant/environment.rb:290:in `cli'\r\n\t15: from /opt/vagrant/embedded/gems/2.2.10/gems/vagrant-2.2.10/lib/vagrant/cli.rb:67:in `execute'\r\n\t14: from /opt/vagrant/embedded/gems/2.2.10/gems/vagrant-2.2.10/plugins/commands/up/command.rb:87:in `execute'\r\n\t13: from /opt/vagrant/embedded/gems/2.2.10/gems/vagrant-2.2.10/lib/vagrant/plugin/v2/command.rb:232:in `with_target_vms'\r\n\t12: from /opt/vagrant/embedded/gems/2.2.10/gems/vagrant-2.2.10/lib/vagrant/plugin/v2/command.rb:232:in `each'\r\n\t11: from /opt/vagrant/embedded/gems/2.2.10/gems/vagrant-2.2.10/lib/vagrant/plugin/v2/command.rb:233:in `block in with_target_vms'\r\n\t10: from /opt/vagrant/embedded/gems/2.2.10/gems/vagrant-2.2.10/lib/vagrant/machine_index.rb:150:in `include?'\r\n\t 9: from /opt/vagrant/embedded/lib/ruby/2.6.0/monitor.rb:235:in `mon_synchronize'\r\n\t 8: from /opt/vagrant/embedded/gems/2.2.10/gems/vagrant-2.2.10/lib/vagrant/machine_index.rb:151:in `block in include?'\r\n\t 7: from /opt/vagrant/embedded/gems/2.2.10/gems/vagrant-2.2.10/lib/vagrant/machine_index.rb:347:in `with_index_lock'\r\n\t 6: from /opt/vagrant/embedded/gems/2.2.10/gems/vagrant-2.2.10/lib/vagrant/machine_index.rb:347:in `open'\r\n\t 5: from /opt/vagrant/embedded/gems/2.2.10/gems/vagrant-2.2.10/lib/vagrant/machine_index.rb:349:in `block in with_index_lock'\r\n\t 4: from /opt/vagrant/embedded/gems/2.2.10/gems/vagrant-2.2.10/lib/vagrant/machine_index.rb:153:in `block (2 levels) in include?'\r\n\t 3: from /opt/vagrant/embedded/gems/2.2.10/gems/vagrant-2.2.10/lib/vagrant/machine_index.rb:266:in `find_by_prefix'\r\n\t 2: from /opt/vagrant/embedded/gems/2.2.10/gems/vagrant-2.2.10/lib/vagrant/machine_index.rb:266:in `each'\r\n\t 1: from /opt/vagrant/embedded/gems/2.2.10/gems/vagrant-2.2.10/lib/vagrant/machine_index.rb:267:in `block in find_by_prefix'\r\n/opt/vagrant/embedded/gems/2.2.10/gems/vagrant-2.2.10/lib/vagrant/machine_index.rb:267:in `start_with?': no implicit conversion of nil into String (TypeError)\r\n```\r\n\r\nVagrantfile:\r\n\r\n```\r\n# -*- mode: ruby -*-\r\n# vi: set ft=ruby :\r\n\r\nVAGRANTFILE_API_VERSION = \"2\"\r\n\r\nVagrant.configure(VAGRANTFILE_API_VERSION) do |config|\r\n  config.vm.box = \"ubuntu/precise64\"\r\n  config.vm.box_check_update = false\r\n\r\n  config.vm.network \"forwarded_port\", guest: 22, host: 2200, id: 'ssh', auto_correct: true\r\n  config.vm.network \"private_network\", ip: \"192.168.33.103\"\r\n  config.vm.network \"public_network\", :bridge => 'enp4s0'\r\n\r\n  config.vm.synced_folder \".\", \"/vagrant\", type: \"nfs\", nfs_udp: false\r\n\r\n  config.vm.provider :virtualbox do |vb|\r\n    vb.name = 'zope'\r\n    vb.memory = 2048\r\n    vb.customize [\"modifyvm\", :id, \"--cpus\", 2]\r\n  end\r\n  \r\n  config.vm.hostname = 'zope'\r\n\r\nend\r\n```\r\n\r\nHost OS: Linux Mint 20, guest: Ubuntu 12.04 (64bit). Virtualbox version 6.1.12. Vagrant v2.2.9 works correctly","performed_via_github_app":null,"score":1.0},{"url":"https://api.github.com/repos/web2py/py4web/issues/318","repository_url":"https://api.github.com/repos/web2py/py4web","labels_url":"https://api.github.com/repos/web2py/py4web/issues/318/labels{/name}","comments_url":"https://api.github.com/repos/web2py/py4web/issues/318/comments","events_url":"https://api.github.com/repos/web2py/py4web/issues/318/events","html_url":"https://github.com/web2py/py4web/issues/318","id":724057676,"node_id":"MDU6SXNzdWU3MjQwNTc2NzY=","number":318,"title":"As cloned Py4web \"run apps\" fails loading examples","user":{"login":"BigBaaadBob","id":102284,"node_id":"MDQ6VXNlcjEwMjI4NA==","avatar_url":"https://avatars0.githubusercontent.com/u/102284?v=4","gravatar_id":"","url":"https://api.github.com/users/BigBaaadBob","html_url":"https://github.com/BigBaaadBob","followers_url":"https://api.github.com/users/BigBaaadBob/followers","following_url":"https://api.github.com/users/BigBaaadBob/following{/other_user}","gists_url":"https://api.github.com/users/BigBaaadBob/gists{/gist_id}","starred_url":"https://api.github.com/users/BigBaaadBob/starred{/owner}{/repo}","subscriptions_url":"https://api.github.com/users/BigBaaadBob/subscriptions","organizations_url":"https://api.github.com/users/BigBaaadBob/orgs","repos_url":"https://api.github.com/users/BigBaaadBob/repos","events_url":"https://api.github.com/users/BigBaaadBob/events{/privacy}","received_events_url":"https://api.github.com/users/BigBaaadBob/received_events","type":"User","site_admin":false},"labels":[],"state":"closed","locked":false,"assignee":null,"assignees":[],"milestone":null,"comments":7,"created_at":"2020-10-18T17:34:13Z","updated_at":"2020-10-18T18:59:19Z","closed_at":"2020-10-18T18:59:19Z","author_association":"NONE","active_lock_reason":null,"body":"Windows 10 Pro, Python 3.8.5\r\n\r\nCloned py4web just now, following the instructions in the documentation:\r\n```\r\ngit clone https://github.com/web2py/py4web.git\r\ncd py4web\r\npython3 -m pip install -r requirements.txt\r\npython3 py4web.py setup apps\r\npython3 py4web.py set_password\r\npython3 py4web.py run apps\r\n```\r\n\r\nThe \"run apps\" step fails loading the examples application:\r\n```\r\n$ python3 py4web.py run apps\r\n\r\n██████╗ ██╗   ██╗██╗  ██╗██╗    ██╗███████╗██████╗\r\n██╔══██╗╚██╗ ██╔╝██║  ██║██║    ██║██╔════╝██╔══██╗\r\n██████╔╝ ╚████╔╝ ███████║██║ █╗ ██║█████╗  ██████╔╝\r\n██╔═══╝   ╚██╔╝  ╚════██║██║███╗██║██╔══╝  ██╔══██╗\r\n██║        ██║        ██║╚███╔███╔╝███████╗██████╔╝\r\n╚═╝        ╚═╝        ╚═╝ ╚══╝╚══╝ ╚══════╝╚═════╝\r\nIs still experimental...\r\n\r\nPy4web: 1.20201008.1 on Python 3.8.5 (default, Sep  3 2020, 21:29:08) [MSC v.1916 64 bit (AMD64)]\r\n\r\n\r\nDashboard is at: http://127.0.0.1:8000/_dashboard\r\n[ ] loading examples ...\r\nTraceback (most recent call last):\r\n  File \"C:\\Users\\witr\\Documents\\Python Scripts\\py4web\\py4web\\core.py\", line 1029, in import_app\r\n    module = importlib.machinery.SourceFileLoader(\r\n  File \"<frozen importlib._bootstrap_external>\", line 462, in _check_name_wrapper\r\n  File \"<frozen importlib._bootstrap_external>\", line 962, in load_module\r\n  File \"<frozen importlib._bootstrap_external>\", line 787, in load_module\r\n  File \"<frozen importlib._bootstrap>\", line 265, in _load_module_shim\r\n  File \"<frozen importlib._bootstrap>\", line 702, in _load\r\n  File \"<frozen importlib._bootstrap>\", line 671, in _load_unlocked\r\n  File \"<frozen importlib._bootstrap_external>\", line 783, in exec_module\r\n  File \"<frozen importlib._bootstrap>\", line 219, in _call_with_frames_removed\r\n  File \"apps\\examples\\__init__.py\", line 7, in <module>\r\n    from .models import db\r\n  File \"apps\\examples\\models.py\", line 6, in <module>\r\n    from .common import db, Field, T, auth\r\n  File \"apps\\examples\\common.py\", line 77, in <module>\r\n    auth.define_tables()\r\n  File \"C:\\Users\\witr\\Documents\\Python Scripts\\py4web\\py4web\\utils\\auth.py\", line 257, in define_tables\r\n    db.define_table(\"auth_user\", *auth_fields, *self.extra_auth_user_fields)\r\n  File \"C:\\Users\\witr\\miniconda3\\envs\\py4web\\lib\\site-packages\\pydal\\base.py\", line 660, in define_table\r\n    table = self.lazy_define_table(tablename, *fields, **kwargs)\r\n  File \"C:\\Users\\witr\\miniconda3\\envs\\py4web\\lib\\site-packages\\pydal\\base.py\", line 697, in lazy_define_table\r\n    self._adapter.create_table(\r\n  File \"C:\\Users\\witr\\miniconda3\\envs\\py4web\\lib\\site-packages\\pydal\\adapters\\base.py\", line 920, in create_table\r\n    return self.migrator.create_table(*args, **kwargs)\r\n  File \"C:\\Users\\witr\\miniconda3\\envs\\py4web\\lib\\site-packages\\pydal\\migrator.py\", line 331, in create_table\r\n    self.log(\r\n  File \"C:\\Users\\witr\\miniconda3\\envs\\py4web\\lib\\site-packages\\pydal\\migrator.py\", line 579, in log\r\n    logfile = self.file_open(table._loggername, \"ab\")\r\n  File \"C:\\Users\\witr\\miniconda3\\envs\\py4web\\lib\\site-packages\\pydal\\migrator.py\", line 587, in file_open\r\n    fileobj = portalocker.LockedFile(filename, mode)\r\n  File \"C:\\Users\\witr\\miniconda3\\envs\\py4web\\lib\\site-packages\\pydal\\contrib\\portalocker.py\", line 186, in __init__\r\n    self.file = open_file(filename, mode.replace(\"w\", \"a\"))\r\n  File \"C:\\Users\\witr\\miniconda3\\envs\\py4web\\lib\\site-packages\\pydal\\contrib\\portalocker.py\", line 171, in open_file\r\n    f = open(filename, mode)\r\nFileNotFoundError: [Errno 2] No such file or directory: 'apps\\\\examples\\\\databases\\\\sql.log'\r\n[FAILED] loading examples\r\nTraceback (most recent call last):\r\n  File \"C:\\Users\\witr\\Documents\\Python Scripts\\py4web\\py4web\\core.py\", line 1029, in import_app\r\n    module = importlib.machinery.SourceFileLoader(\r\n  File \"<frozen importlib._bootstrap_external>\", line 462, in _check_name_wrapper\r\n  File \"<frozen importlib._bootstrap_external>\", line 962, in load_module\r\n  File \"<frozen importlib._bootstrap_external>\", line 787, in load_module\r\n  File \"<frozen importlib._bootstrap>\", line 265, in _load_module_shim\r\n  File \"<frozen importlib._bootstrap>\", line 702, in _load\r\n  File \"<frozen importlib._bootstrap>\", line 671, in _load_unlocked\r\n  File \"<frozen importlib._bootstrap_external>\", line 783, in exec_module\r\n  File \"<frozen importlib._bootstrap>\", line 219, in _call_with_frames_removed\r\n  File \"apps\\examples\\__init__.py\", line 7, in <module>\r\n    from .models import db\r\n  File \"apps\\examples\\models.py\", line 6, in <module>\r\n    from .common import db, Field, T, auth\r\n  File \"apps\\examples\\common.py\", line 77, in <module>\r\n    auth.define_tables()\r\n  File \"C:\\Users\\witr\\Documents\\Python Scripts\\py4web\\py4web\\utils\\auth.py\", line 257, in define_tables\r\n    db.define_table(\"auth_user\", *auth_fields, *self.extra_auth_user_fields)\r\n  File \"C:\\Users\\witr\\miniconda3\\envs\\py4web\\lib\\site-packages\\pydal\\base.py\", line 660, in define_table\r\n    table = self.lazy_define_table(tablename, *fields, **kwargs)\r\n  File \"C:\\Users\\witr\\miniconda3\\envs\\py4web\\lib\\site-packages\\pydal\\base.py\", line 697, in lazy_define_table\r\n    self._adapter.create_table(\r\n  File \"C:\\Users\\witr\\miniconda3\\envs\\py4web\\lib\\site-packages\\pydal\\adapters\\base.py\", line 920, in create_table\r\n    return self.migrator.create_table(*args, **kwargs)\r\n  File \"C:\\Users\\witr\\miniconda3\\envs\\py4web\\lib\\site-packages\\pydal\\migrator.py\", line 331, in create_table\r\n    self.log(\r\n  File \"C:\\Users\\witr\\miniconda3\\envs\\py4web\\lib\\site-packages\\pydal\\migrator.py\", line 579, in log\r\n    logfile = self.file_open(table._loggername, \"ab\")\r\n  File \"C:\\Users\\witr\\miniconda3\\envs\\py4web\\lib\\site-packages\\pydal\\migrator.py\", line 587, in file_open\r\n    fileobj = portalocker.LockedFile(filename, mode)\r\n  File \"C:\\Users\\witr\\miniconda3\\envs\\py4web\\lib\\site-packages\\pydal\\contrib\\portalocker.py\", line 186, in __init__\r\n    self.file = open_file(filename, mode.replace(\"w\", \"a\"))\r\n  File \"C:\\Users\\witr\\miniconda3\\envs\\py4web\\lib\\site-packages\\pydal\\contrib\\portalocker.py\", line 171, in open_file\r\n    f = open(filename, mode)\r\nFileNotFoundError: [Errno 2] No such file or directory: 'apps\\\\examples\\\\databases\\\\sql.log'\r\n\r\n\r\n[X] loaded myfeed\r\n[X] loaded todo\r\n[X] loaded _dashboard\r\n[X] loaded _default\r\n[X] loaded _documentation\r\n[X] loaded _minimal\r\n[X] loaded _scaffold\r\nBottle v0.12.18 server starting up (using TornadoServer())...\r\nListening on http://127.0.0.1:8000/\r\nHit Ctrl-C to quit.\r\n```\r\n","performed_via_github_app":null,"score":1.0},{"url":"https://api.github.com/repos/web2py/web2py/issues/2317","repository_url":"https://api.github.com/repos/web2py/web2py","labels_url":"https://api.github.com/repos/web2py/web2py/issues/2317/labels{/name}","comments_url":"https://api.github.com/repos/web2py/web2py/issues/2317/comments","events_url":"https://api.github.com/repos/web2py/web2py/issues/2317/events","html_url":"https://github.com/web2py/web2py/issues/2317","id":611878393,"node_id":"MDU6SXNzdWU2MTE4NzgzOTM=","number":2317,"title":"Plugin app BUG on 2.19.1 version with python 3.7 - SOLVED","user":{"login":"attiquetecnologia","id":13678354,"node_id":"MDQ6VXNlcjEzNjc4MzU0","avatar_url":"https://avatars3.githubusercontent.com/u/13678354?v=4","gravatar_id":"","url":"https://api.github.com/users/attiquetecnologia","html_url":"https://github.com/attiquetecnologia","followers_url":"https://api.github.com/users/attiquetecnologia/followers","following_url":"https://api.github.com/users/attiquetecnologia/following{/other_user}","gists_url":"https://api.github.com/users/attiquetecnologia/gists{/gist_id}","starred_url":"https://api.github.com/users/attiquetecnologia/starred{/owner}{/repo}","subscriptions_url":"https://api.github.com/users/attiquetecnologia/subscriptions","organizations_url":"https://api.github.com/users/attiquetecnologia/orgs","repos_url":"https://api.github.com/users/attiquetecnologia/repos","events_url":"https://api.github.com/users/attiquetecnologia/events{/privacy}","received_events_url":"https://api.github.com/users/attiquetecnologia/received_events","type":"User","site_admin":false},"labels":[],"state":"closed","locked":false,"assignee":null,"assignees":[],"milestone":null,"comments":2,"created_at":"2020-05-04T13:32:53Z","updated_at":"2020-05-27T12:52:05Z","closed_at":"2020-05-27T12:52:05Z","author_association":"NONE","active_lock_reason":null,"body":"**Describe the bug**\r\nA ticket generate when I try install new plugins on my app. Using the python 3.7. The web2py used is 2.19.1.\r\n\r\n**To Reproduce**\r\nSteps to reproduce the behavior:\r\n1. Go to appadmin of app\r\n2. Click in Plugins\r\n3. Click in installed plugin\r\n4. See error\r\n\r\n**Expected behavior**\r\nTicket number\r\n127.0.0.1.2020-05-04.10-23-24.0c4a822a-07ec-4977-afa7-422444fe6c69\r\n<class 'NameError'> name 'regex_tables' is not defined\r\n\r\nVersion\r\nweb2py™ | Version 2.19.1-stable+timestamp.2020.03.21.21.49.28\r\nPython 3.7.7: C:\\Python37\\python.exe (prefix: C:\\Python37)\r\n\r\n**Screenshots**\r\nhttps://1.bp.blogspot.com/-KdppqUKuCJg/XrAZF4Maj5I/AAAAAAAACy0/DMvCwa9UGMctXbZKN_HtxyM1c3z6FSZggCLcBGAsYHQ/s1600/ticket1.JPG\r\n\r\nhttps://1.bp.blogspot.com/-K5lbD7JyfgA/XrAZGzCB_lI/AAAAAAAACy4/RKJpFRQ-H-QEE_OZOpUZgGmfMmgZBM7GgCLcBGAsYHQ/s1600/ticket2.JPG\r\n\r\nhttps://1.bp.blogspot.com/-8lLMxOTR8sc/XrAZISkIDBI/AAAAAAAACy8/H-UWKpiilag3_zO5p_OB9snTPGJDiwhfQCLcBGAsYHQ/s1600/ticket3.JPG\r\n\r\n\r\n**Additional context**\r\nAdd any other context about the problem here.\r\n","performed_via_github_app":null,"score":1.0},{"url":"https://api.github.com/repos/peppelinux/Ansible-Shibboleth-IDP-SP-Debian/issues/13","repository_url":"https://api.github.com/repos/peppelinux/Ansible-Shibboleth-IDP-SP-Debian","labels_url":"https://api.github.com/repos/peppelinux/Ansible-Shibboleth-IDP-SP-Debian/issues/13/labels{/name}","comments_url":"https://api.github.com/repos/peppelinux/Ansible-Shibboleth-IDP-SP-Debian/issues/13/comments","events_url":"https://api.github.com/repos/peppelinux/Ansible-Shibboleth-IDP-SP-Debian/issues/13/events","html_url":"https://github.com/peppelinux/Ansible-Shibboleth-IDP-SP-Debian/issues/13","id":663532558,"node_id":"MDU6SXNzdWU2NjM1MzI1NTg=","number":13,"title":"Excellent work!","user":{"login":"ljudva","id":36252744,"node_id":"MDQ6VXNlcjM2MjUyNzQ0","avatar_url":"https://avatars0.githubusercontent.com/u/36252744?v=4","gravatar_id":"","url":"https://api.github.com/users/ljudva","html_url":"https://github.com/ljudva","followers_url":"https://api.github.com/users/ljudva/followers","following_url":"https://api.github.com/users/ljudva/following{/other_user}","gists_url":"https://api.github.com/users/ljudva/gists{/gist_id}","starred_url":"https://api.github.com/users/ljudva/starred{/owner}{/repo}","subscriptions_url":"https://api.github.com/users/ljudva/subscriptions","organizations_url":"https://api.github.com/users/ljudva/orgs","repos_url":"https://api.github.com/users/ljudva/repos","events_url":"https://api.github.com/users/ljudva/events{/privacy}","received_events_url":"https://api.github.com/users/ljudva/received_events","type":"User","site_admin":false},"labels":[],"state":"closed","locked":false,"assignee":null,"assignees":[],"milestone":null,"comments":8,"created_at":"2020-07-22T07:13:27Z","updated_at":"2020-07-22T11:41:40Z","closed_at":"2020-07-22T11:41:40Z","author_association":"NONE","active_lock_reason":null,"body":"Hi Giuseppe,\r\n\r\nexcellent work! There are a number of changes for VirtualBox to work but I got there. \r\n\r\n020-07-22 00:08:18,267 - 10.0.2.2 - INFO [org.ldaptive.auth.Authenticator:291] - Authentication succeeded for dn: uid=gino,ou=people,dc=testunical,dc=it\r\n\r\n\r\n![idpIT01](https://user-images.githubusercontent.com/36252744/88145677-62b75c80-cc2d-11ea-9e69-b46b1afd1dc2.png)\r\n\r\nAfter this, getting opensaml::FatalProfileException at (https://sp.testunical.it:4443/Shibboleth.sso/SAML2/POST) \r\n\r\nUnable to establish security of incoming assertion.\r\n\r\nCan we not sign the assertion or something? I'm not familiar with Apache Shib module.\r\n\r\nAny ideas?\r\n\r\nHere is the metadata:\r\n```\r\ndebian:/home/jampy# grep --color -R \"https://idp.testunical.it:444\" /etc/shibboleth/*\r\n/etc/shibboleth/metadata/idp.testunical.it-metadata.xml:<EntityDescriptor  xmlns=\"urn:oasis:names:tc:SAML:2.0:metadata\" xmlns:ds=\"http://www.w3.org/2000/09/xmldsig#\" xmlns:shibmd=\"urn:mace:shibboleth:metadata:1.0\" xmlns:xml=\"http://www.w3.org/XML/1998/namespace\" xmlns:mdui=\"urn:oasis:names:tc:SAML:metadata:ui\" xmlns:req-attr=\"urn:oasis:names:tc:SAML:protocol:ext:req-attr\"  entityID=\"https://idp.testunical.it:4443/idp/shibboleth\">\r\n/etc/shibboleth/metadata/idp.testunical.it-metadata.xml:                <mdui:Logo height=\"80\" width=\"80\">https://idp.testunical.it:4443/Path/To/Logo.png</mdui:Logo>\r\n/etc/shibboleth/metadata/idp.testunical.it-metadata.xml:        <SingleLogoutService Binding=\"urn:oasis:names:tc:SAML:2.0:bindings:HTTP-POST\" Location=\"https://idp.testunical.it:4443/idp/profile/SAML2/POST/SLO\"/>\r\n/etc/shibboleth/metadata/idp.testunical.it-metadata.xml:        <SingleLogoutService Binding=\"urn:oasis:names:tc:SAML:2.0:bindings:HTTP-POST-SimpleSign\" Location=\"https://idp.testunical.it:4443/idp/profile/SAML2/POST-SimpleSign/SLO\"/>\r\n/etc/shibboleth/metadata/idp.testunical.it-metadata.xml:        <SingleLogoutService Binding=\"urn:oasis:names:tc:SAML:2.0:bindings:HTTP-Redirect\" Location=\"https://idp.testunical.it:4443/idp/profile/SAML2/Redirect/SLO\"/>\r\n/etc/shibboleth/metadata/idp.testunical.it-metadata.xml:        <SingleLogoutService Binding=\"urn:oasis:names:tc:SAML:2.0:bindings:SOAP\" Location=\"https://idp.testunical.it:4443/idp/profile/SAML2/SOAP/SLO\"/>\r\n/etc/shibboleth/metadata/idp.testunical.it-metadata.xml: <SingleSignOnService Binding=\"urn:oasis:names:tc:SAML:2.0:bindings:HTTP-POST-SimpleSign\" req-attr:supportsRequestedAttributes=\"true\" Location=\"https://idp.testunical.it:4443/idp/profile/SAML2/POST-SimpleSign/SSO\"/>\r\n/etc/shibboleth/metadata/idp.testunical.it-metadata.xml:        <SingleSignOnService Binding=\"urn:oasis:names:tc:SAML:2.0:bindings:HTTP-Redirect\" req-attr:supportsRequestedAttributes=\"true\" Location=\"https://idp.testunical.it:4443/idp/profile/SAML2/Redirect/SSO\"/>\r\n/etc/shibboleth/metadata/idp.testunical.it-metadata.xml:        <SingleSignOnService Binding=\"urn:oasis:names:tc:SAML:2.0:bindings:HTTP-POST\" req-attr:supportsRequestedAttributes=\"true\" Location=\"https://idp.testunical.it:4443/idp/profile/SAML2/POST/SSO\"/>\r\n/etc/shibboleth/metadata/idp.testunical.it-metadata.xml:        <AttributeService Binding=\"urn:oasis:names:tc:SAML:2.0:bindings:SOAP\" Location=\"https://idp.testunical.it:4443/idp/profile/SAML2/SOAP/AttributeQuery\"/>\r\n/etc/shibboleth/shibboleth2.xml:                              entityID=\"https://idp.testunical.it:4443/idp/shibboleth\">\r\n```\r\nAnd the log:\r\n```\r\n2020-07-21 23:47:13 WARN Shibboleth.SessionInitiator.SAML2 [8] [default]: unable to locate metadata for provider (https://idp.testunical.it:4443/idp/shibboleth)\r\n2020-07-22 00:11:00 WARN OpenSAML.MessageDecoder.SAML2 [11] [default]: no metadata found, can't establish identity of issuer (https://idp.testunical.it/idp/shibboleth)\r\n2020-07-22 00:11:00 WARN Shibboleth.SSO.SAML2 [11] [default]: no metadata found, can't establish identity of issuer (https://idp.testunical.it/idp/shibboleth)\r\n2020-07-22 00:11:00 WARN Shibboleth.SSO.SAML2 [11] [default]: detected a problem with assertion: Unable to establish security of incoming assertion.\r\n```\r\n\r\nNot sure why is using https://idp.testunical.it/idp/shibboleth for identity when accessed by https://idp.testunical.it:4443/idp/shibboleth\r\n\r\n\r\nThanks\r\nCheers","performed_via_github_app":null,"score":1.0},{"url":"https://api.github.com/repos/web2py/py4web/issues/202","repository_url":"https://api.github.com/repos/web2py/py4web","labels_url":"https://api.github.com/repos/web2py/py4web/issues/202/labels{/name}","comments_url":"https://api.github.com/repos/web2py/py4web/issues/202/comments","events_url":"https://api.github.com/repos/web2py/py4web/issues/202/events","html_url":"https://github.com/web2py/py4web/issues/202","id":621236315,"node_id":"MDU6SXNzdWU2MjEyMzYzMTU=","number":202,"title":"Watchgod issues","user":{"login":"pdralston","id":25166909,"node_id":"MDQ6VXNlcjI1MTY2OTA5","avatar_url":"https://avatars0.githubusercontent.com/u/25166909?v=4","gravatar_id":"","url":"https://api.github.com/users/pdralston","html_url":"https://github.com/pdralston","followers_url":"https://api.github.com/users/pdralston/followers","following_url":"https://api.github.com/users/pdralston/following{/other_user}","gists_url":"https://api.github.com/users/pdralston/gists{/gist_id}","starred_url":"https://api.github.com/users/pdralston/starred{/owner}{/repo}","subscriptions_url":"https://api.github.com/users/pdralston/subscriptions","organizations_url":"https://api.github.com/users/pdralston/orgs","repos_url":"https://api.github.com/users/pdralston/repos","events_url":"https://api.github.com/users/pdralston/events{/privacy}","received_events_url":"https://api.github.com/users/pdralston/received_events","type":"User","site_admin":false},"labels":[],"state":"closed","locked":false,"assignee":null,"assignees":[],"milestone":null,"comments":34,"created_at":"2020-05-19T19:40:43Z","updated_at":"2020-10-05T06:13:51Z","closed_at":"2020-10-05T06:09:49Z","author_association":"NONE","active_lock_reason":null,"body":"With the latest pull, watchgod is enabled. I have observed 2 issues with it so far.\r\n1. When running the server using anaconda prompt, pressing Ctrl+C fails to interrupt the server as expected. Pressing the command twice seems to shut down the server as expected. This behavior is not observed when using WSL or PyCharm\r\n2. When testing watchgod functionality, I changed a minor value in a python value, the watcher saw the change and reported that it reloaded the application in question. Upon hard refreshing I get a 500 error. Restarting the server manually allows the application to load in the browser as expected.","performed_via_github_app":null,"score":1.0},{"url":"https://api.github.com/repos/web2py/pydal/issues/611","repository_url":"https://api.github.com/repos/web2py/pydal","labels_url":"https://api.github.com/repos/web2py/pydal/issues/611/labels{/name}","comments_url":"https://api.github.com/repos/web2py/pydal/issues/611/comments","events_url":"https://api.github.com/repos/web2py/pydal/issues/611/events","html_url":"https://github.com/web2py/pydal/issues/611","id":570730671,"node_id":"MDU6SXNzdWU1NzA3MzA2NzE=","number":611,"title":"Firebird Adaptor needs test_connection","user":{"login":"villas","id":4347549,"node_id":"MDQ6VXNlcjQzNDc1NDk=","avatar_url":"https://avatars3.githubusercontent.com/u/4347549?v=4","gravatar_id":"","url":"https://api.github.com/users/villas","html_url":"https://github.com/villas","followers_url":"https://api.github.com/users/villas/followers","following_url":"https://api.github.com/users/villas/following{/other_user}","gists_url":"https://api.github.com/users/villas/gists{/gist_id}","starred_url":"https://api.github.com/users/villas/starred{/owner}{/repo}","subscriptions_url":"https://api.github.com/users/villas/subscriptions","organizations_url":"https://api.github.com/users/villas/orgs","repos_url":"https://api.github.com/users/villas/repos","events_url":"https://api.github.com/users/villas/events{/privacy}","received_events_url":"https://api.github.com/users/villas/received_events","type":"User","site_admin":false},"labels":[],"state":"closed","locked":false,"assignee":null,"assignees":[],"milestone":null,"comments":5,"created_at":"2020-02-25T17:39:21Z","updated_at":"2020-05-15T13:59:39Z","closed_at":"2020-05-15T13:59:38Z","author_association":"CONTRIBUTOR","active_lock_reason":null,"body":"The base.py test_connection ('SELECT 1;') does not work for Firebird because a FROM clause is obligatory.   Therefore,  I suggest using a system table.  This works for me...\r\n\r\n    def test_connection(self):\r\n        self.execute('SELECT 1 FROM RDB$RELATION_FIELDS WHERE 1=0')\r\n\r\nPlease add this to pydal/adapters/firebird.py.  \r\nThanks.","performed_via_github_app":null,"score":1.0},{"url":"https://api.github.com/repos/web2py/web2py/issues/2217","repository_url":"https://api.github.com/repos/web2py/web2py","labels_url":"https://api.github.com/repos/web2py/web2py/issues/2217/labels{/name}","comments_url":"https://api.github.com/repos/web2py/web2py/issues/2217/comments","events_url":"https://api.github.com/repos/web2py/web2py/issues/2217/events","html_url":"https://github.com/web2py/web2py/issues/2217","id":451443957,"node_id":"MDU6SXNzdWU0NTE0NDM5NTc=","number":2217,"title":"Missing bootstrap4 and row class in addrow method","user":{"login":"romicasal","id":2307548,"node_id":"MDQ6VXNlcjIzMDc1NDg=","avatar_url":"https://avatars0.githubusercontent.com/u/2307548?v=4","gravatar_id":"","url":"https://api.github.com/users/romicasal","html_url":"https://github.com/romicasal","followers_url":"https://api.github.com/users/romicasal/followers","following_url":"https://api.github.com/users/romicasal/following{/other_user}","gists_url":"https://api.github.com/users/romicasal/gists{/gist_id}","starred_url":"https://api.github.com/users/romicasal/starred{/owner}{/repo}","subscriptions_url":"https://api.github.com/users/romicasal/subscriptions","organizations_url":"https://api.github.com/users/romicasal/orgs","repos_url":"https://api.github.com/users/romicasal/repos","events_url":"https://api.github.com/users/romicasal/events{/privacy}","received_events_url":"https://api.github.com/users/romicasal/received_events","type":"User","site_admin":false},"labels":[],"state":"closed","locked":false,"assignee":null,"assignees":[],"milestone":null,"comments":1,"created_at":"2019-06-03T12:01:37Z","updated_at":"2020-03-21T19:40:44Z","closed_at":"2020-03-21T19:40:43Z","author_association":"NONE","active_lock_reason":null,"body":"Hello, I'm using recaptcha in auth settings but form is not showing as expected.\r\nI solved this adding bootstrap4 condition:\r\n\r\n`elif style in (\"bootstrap3_inline\", \"bootstrap4_inline\")`\r\n\r\n`elif style in (\"bootstrap3_stacked\", \"bootstrap4_stacked\")`\r\n\r\n\r\nhttps://github.com/web2py/web2py/blob/409a499dd014195c5a7945eb3d160104bdce5341/gluon/tools.py#L987\r\n\r\nhttps://github.com/web2py/web2py/blob/409a499dd014195c5a7945eb3d160104bdce5341/gluon/tools.py#L992\r\n\r\nAnd adding 'row' to \r\n\r\nhttps://github.com/web2py/web2py/blob/409a499dd014195c5a7945eb3d160104bdce5341/gluon/tools.py#L991\r\nhttps://github.com/web2py/web2py/blob/409a499dd014195c5a7945eb3d160104bdce5341/gluon/tools.py#L995\r\n\r\n","performed_via_github_app":null,"score":1.0},{"url":"https://api.github.com/repos/sahana/eden/issues/1541","repository_url":"https://api.github.com/repos/sahana/eden","labels_url":"https://api.github.com/repos/sahana/eden/issues/1541/labels{/name}","comments_url":"https://api.github.com/repos/sahana/eden/issues/1541/comments","events_url":"https://api.github.com/repos/sahana/eden/issues/1541/events","html_url":"https://github.com/sahana/eden/issues/1541","id":599798945,"node_id":"MDU6SXNzdWU1OTk3OTg5NDU=","number":1541,"title":"translate_gis_location + non-english language cause translation export error","user":{"login":"trendspotter","id":15286128,"node_id":"MDQ6VXNlcjE1Mjg2MTI4","avatar_url":"https://avatars1.githubusercontent.com/u/15286128?v=4","gravatar_id":"","url":"https://api.github.com/users/trendspotter","html_url":"https://github.com/trendspotter","followers_url":"https://api.github.com/users/trendspotter/followers","following_url":"https://api.github.com/users/trendspotter/following{/other_user}","gists_url":"https://api.github.com/users/trendspotter/gists{/gist_id}","starred_url":"https://api.github.com/users/trendspotter/starred{/owner}{/repo}","subscriptions_url":"https://api.github.com/users/trendspotter/subscriptions","organizations_url":"https://api.github.com/users/trendspotter/orgs","repos_url":"https://api.github.com/users/trendspotter/repos","events_url":"https://api.github.com/users/trendspotter/events{/privacy}","received_events_url":"https://api.github.com/users/trendspotter/received_events","type":"User","site_admin":false},"labels":[],"state":"closed","locked":false,"assignee":null,"assignees":[],"milestone":null,"comments":0,"created_at":"2020-04-14T19:14:41Z","updated_at":"2020-04-15T15:54:41Z","closed_at":"2020-04-15T15:54:41Z","author_association":"CONTRIBUTOR","active_lock_reason":null,"body":"When `settings.L10n.translate_gis_location = True` and `current.session.s3.language != \"en\"`, full translation exports (i.e. including \"_Select all templates (All modules included)_\") fail with\r\n```\r\nTraceback (most recent call last):\r\n  File \"/srv/web2py/gluon/restricted.py\", line 219, in restricted\r\n    exec(ccode, environment)\r\n  File \"/srv/web2py/applications/eden/controllers/admin.py\", line 1292, in <module>\r\n  File \"/srv/web2py/gluon/globals.py\", line 421, in <lambda>\r\n    self._caller = lambda f: f()\r\n  File \"/srv/web2py/applications/eden/controllers/admin.py\", line 1215, in translate\r\n    output = s3_rest_controller(\"translate\", \"language\")\r\n  File \"/srv/web2py/applications/eden/models/00_utils.py\", line 245, in s3_rest_controller\r\n    output = r(**attr)\r\n  File \"/srv/web2py/applications/eden/modules/s3/s3rest.py\", line 697, in __call__\r\n    output = postprocess(self, output)\r\n  File \"/srv/web2py/applications/eden/controllers/admin.py\", line 964, in postp\r\n    output = X.export_file(code, modlist, [], filetype, all_template_flag)\r\n  File \"/srv/web2py/applications/eden/modules/s3/s3translate.py\", line 1083, in export_file\r\n    NewStrings += R.get_database_strings(all_template_flag)\r\n  File \"/srv/web2py/applications/eden/modules/s3/s3translate.py\", line 914, in get_database_strings\r\n    if e.lower() in fields:\r\nTypeError: argument of type 'NoneType' is not iterable\r\n```\r\n\r\nThis is consistent with the conditions here:\r\nhttps://github.com/sahana/eden/blob/7a1ebe5fd298b55663db5f2cc0ad99a5b6798346/modules/s3db/gis.py#L5149-L5153\r\nWhere both the translate_gis_location and the language need to be set for `translate` to be `True`. It seems that `gis_LocationRepresent` simply doesn't define any fields which are needed in the `get_database_strings()` above.","performed_via_github_app":null,"score":1.0},{"url":"https://api.github.com/repos/multilang-depends/depends/issues/12","repository_url":"https://api.github.com/repos/multilang-depends/depends","labels_url":"https://api.github.com/repos/multilang-depends/depends/issues/12/labels{/name}","comments_url":"https://api.github.com/repos/multilang-depends/depends/issues/12/comments","events_url":"https://api.github.com/repos/multilang-depends/depends/issues/12/events","html_url":"https://github.com/multilang-depends/depends/issues/12","id":483456324,"node_id":"MDU6SXNzdWU0ODM0NTYzMjQ=","number":12,"title":"cannot complete scan of some projects","user":{"login":"gangz","id":888199,"node_id":"MDQ6VXNlcjg4ODE5OQ==","avatar_url":"https://avatars3.githubusercontent.com/u/888199?v=4","gravatar_id":"","url":"https://api.github.com/users/gangz","html_url":"https://github.com/gangz","followers_url":"https://api.github.com/users/gangz/followers","following_url":"https://api.github.com/users/gangz/following{/other_user}","gists_url":"https://api.github.com/users/gangz/gists{/gist_id}","starred_url":"https://api.github.com/users/gangz/starred{/owner}{/repo}","subscriptions_url":"https://api.github.com/users/gangz/subscriptions","organizations_url":"https://api.github.com/users/gangz/orgs","repos_url":"https://api.github.com/users/gangz/repos","events_url":"https://api.github.com/users/gangz/events{/privacy}","received_events_url":"https://api.github.com/users/gangz/received_events","type":"User","site_admin":false},"labels":[],"state":"closed","locked":false,"assignee":null,"assignees":[],"milestone":null,"comments":5,"created_at":"2019-08-21T14:27:33Z","updated_at":"2020-06-10T05:59:04Z","closed_at":"2020-06-10T05:59:03Z","author_association":"COLLABORATOR","active_lock_reason":null,"body":"\r\nwireshark | https://github.com/wireshark/wireshark | C\r\n-- | -- | --\r\nnetbeans | https://github.com/apache/netbeans | Java\r\nlinux | https://github.com/torvalds/linux | C\r\nflatbuffers | https://github.com/google/flatbuffers | C++\r\nwangle | https://github.com/facebook/wangle | C++\r\nredex | https://github.com/facebook/redex | C++\r\nhhvm | https://github.com/facebook/hhvm | C++\r\ntensorflow | https://github.com/tensorflow/tensorflow | C++\r\nturicreate | https://github.com/apple/turicreate | C++\r\nceph | https://github.com/ceph/ceph | C++\r\nfreebsd | https://github.com/freebsd/freebsd | C++\r\nlibreoffice | https://github.com/LibreOffice/core | C++\r\nsrc | https://github.com/openbsd/src | C++\r\nnode | https://github.com/nodejs/node | C++\r\nnetbsd | https://github.com/NetBSD/src | C++\r\nillumos | https://github.com/illumos/illumos-gate | C++\r\nclang | https://github.com/llvm-mirror/clang | C++\r\nmongoose | https://github.com/cesanta/mongoose | C\r\nmongodb | https://github.com/mongodb/mongo | C++\r\nmariadb | https://github.com/MariaDB/server | C++\r\nopencv | https://github.com/opencv/opencv | C++\r\nmysql | https://github.com/mysql/mysql-server | C++\r\nphp | https://github.com/php/php-src | C++\r\nopenoffice | https://github.com/apache/openoffice | C++\r\nmimetex | https://github.com/MoonchildProductions/Pale-Moon | C++\r\nqt | https://github.com/qt/qt | C++\r\nsequel | https://github.com/jeremyevans/sequel | Ruby\r\nstrongswan | https://github.com/strongswan/strongswan | C++\r\nwine | https://github.com/wine-mirror/wine | C\r\nwebkit | https://github.com/WebKit/webkit | C++\r\ncmake | https://github.com/Kitware/CMake | C\r\nbattle_for_wesnoth | https://github.com/battle-for-wesnoth/svn | C++\r\nmono | https://github.com/mono/mono | C\r\ntraffic_server | https://github.com/apache/trafficserver | C++\r\nstlport | https://github.com/frida/stlport | C++\r\nsolidus | https://github.com/solidusio/solidus | Ruby\r\nlibuv | https://github.com/libuv/libuv | C\r\nkismet | https://github.com/kismetwireless/kismet | C++\r\ndragonfly | https://github.com/markevans/dragonfly | Ruby\r\nyard | https://github.com/lsegal/yard | Ruby\r\nxrootd | https://github.com/xrootd/xrootd | C++\r\nwt | https://github.com/emweb/wt | C\r\ngrape | https://github.com/ruby-grape/grape | Ruby\r\nfpm | https://github.com/jordansissel/fpm | Ruby\r\nfluentd | https://github.com/fluent/fluentd | Ruby\r\nflite | https://github.com/festvox/flite | C\r\nfestivaltts4r | https://github.com/spejman/festivaltts4r | Ruby\r\nelectron | https://github.com/electron/electron | C++\r\ndirectfb | https://github.com/DirectFB/directfb | C\r\ndcmtk | https://github.com/DCMTK/dcmtk | C++\r\ndatabase_rewinder | https://github.com/amatsuda/database_rewinder | Ruby\r\nconky | https://github.com/brndnmtthws/conky | C++\r\nchef | https://github.com/chef/chef | Ruby\r\ncapnproto | https://github.com/capnproto/capnproto | C++\r\nbundler | https://github.com/bundler/bundler | Ruby\r\nactiveadmin | https://github.com/activeadmin/activeadmin | Ruby\r\nopen-iscsi | https://github.com/open-iscsi/open-iscsi | C\r\nnghttp2 | https://github.com/nghttp2/nghttp2 | C++\r\nresiprocate | https://github.com/resiprocate/resiprocate.git | C++\r\nansible | https://github.com/ansible/ansible.git | Python\r\nedx-platform | https://github.com/edx/edx-platform.git | Python\r\ngolismero | https://github.com/golismero/golismero.git | Python\r\nhome-assistant | https://github.com/home-assistant/home-assistant.git | Python\r\npycsw | https://github.com/geopython/pycsw.git | Python\r\nPyro4 | https://github.com/irmen/Pyro4.git | Python\r\npython | https://github.com/spring/Python.git | Python\r\nrequests | https://github.com/kennethreitz/requests.git | Python\r\nscipy | https://github.com/scipy/scipy.git | Python\r\nsentry | https://github.com/getsentry/sentry.git | Python\r\nswift | https://github.com/openstack/swift.git | Python\r\nweb2py | https://github.com/web2py/web2py.git | Python\r\nnova | https://github.com/openstack/nova.git | Python\r\njabberd2 | https://github.com/jabberd2/jabberd2.git | C/C++\r\ncarrierwave | https://github.com/carrierwaveuploader/carrierwave.git | Ruby\r\ngrub2 | https://github.com/rhboot/grub2.git | C/C++\r\njdt-core | https://github.com/eclipse/eclipse.jdt | Java\r\nkamailio | https://github.com/kamailio/kamailio.git | C/C++\r\nnanoc | https://github.com/nanoc/nanoc.git | Ruby\r\nspree | https://github.com/spree/spree.git | Ruby\r\npale_moon | https://github.com/MoonchildProductions/Pale-Moon.git | C/C++\r\npassenger | https://github.com/phusion/passenger.git | C/C++\r\nresiprocate | https://github.com/resiprocate/resiprocate.git | C/C++\r\nclamav | https://github.com/Cisco-Talos/clamav-devel.git | C/C++\r\nrack | https://github.com/rack/rack.git | Ruby\r\ntarantool | https://github.com/tarantool/tarantool.git | C/C++\r\nxorg-server | https://github.com/wereHamster/xorg-server.git | C/C++\r\ncurl | https://github.com/curl/curl.git | C/C++\r\nuclibc | https://github.com/kraj/uClibc.git | C/C++\r\nitextpdf | https://github.com/itext/itextpdf.git | Java\r\nsquid | https://github.com/squid-cache/squid2.git | C/C++\r\ngstreamer | https://github.com/GStreamer/gstreamer.git | C/C++\r\nfreeradius | https://github.com/FreeRADIUS/freeradius-server.git | C/C++\r\n\r\n","performed_via_github_app":null,"score":1.0},{"url":"https://api.github.com/repos/sahana/eden/issues/1545","repository_url":"https://api.github.com/repos/sahana/eden","labels_url":"https://api.github.com/repos/sahana/eden/issues/1545/labels{/name}","comments_url":"https://api.github.com/repos/sahana/eden/issues/1545/comments","events_url":"https://api.github.com/repos/sahana/eden/issues/1545/events","html_url":"https://github.com/sahana/eden/issues/1545","id":603412819,"node_id":"MDU6SXNzdWU2MDM0MTI4MTk=","number":1545,"title":"Wrong link, too few mandatory fields and NoneType error in Assessment Targets (dc module)","user":{"login":"trendspotter","id":15286128,"node_id":"MDQ6VXNlcjE1Mjg2MTI4","avatar_url":"https://avatars1.githubusercontent.com/u/15286128?v=4","gravatar_id":"","url":"https://api.github.com/users/trendspotter","html_url":"https://github.com/trendspotter","followers_url":"https://api.github.com/users/trendspotter/followers","following_url":"https://api.github.com/users/trendspotter/following{/other_user}","gists_url":"https://api.github.com/users/trendspotter/gists{/gist_id}","starred_url":"https://api.github.com/users/trendspotter/starred{/owner}{/repo}","subscriptions_url":"https://api.github.com/users/trendspotter/subscriptions","organizations_url":"https://api.github.com/users/trendspotter/orgs","repos_url":"https://api.github.com/users/trendspotter/repos","events_url":"https://api.github.com/users/trendspotter/events{/privacy}","received_events_url":"https://api.github.com/users/trendspotter/received_events","type":"User","site_admin":false},"labels":[],"state":"closed","locked":false,"assignee":null,"assignees":[],"milestone":null,"comments":2,"created_at":"2020-04-20T17:37:17Z","updated_at":"2020-04-21T14:16:54Z","closed_at":"2020-04-21T14:16:53Z","author_association":"CONTRIBUTOR","active_lock_reason":null,"body":"**Steps to reproduce:**\r\n1. Log in on an instance with Assessments (dc) module enabled\r\n2. Go to *Assessments* -> *Templates* -> *Create*\r\n3. Create a new template, fill in only mandatory fields (name)\r\n4. Go to *Assessments* -> *Targets* -> *Create*\r\n5. Create a new target, fill in only mandatory fields (template from step 3)\r\n6. Click on *Report*\r\n\r\n**Problem 1)**  \r\nData Collection Target name should be mandatory. If not given, the target is called \"*None*\".\r\n\r\n**Problem 2)**  \r\n*Report* href leads to `/eden/dc/results?viewing=dc_target.1`. This is presumably caused by the slash at the end of https://github.com/sahana/eden/blob/a1b1831b9d694c4cd0911767e2e656d31ca9012c/modules/s3db/dc.py#L2379\r\n\r\n**Problem 3)**  \r\nAfter manually navigating to `/eden/dc/target/1/results`, error 500 with following traceback is produced\r\n```\r\nTraceback (most recent call last):\r\n  File \"/srv/web2py/gluon/restricted.py\", line 219, in restricted\r\n    exec(ccode, environment)\r\n  File \"/srv/web2py/applications/eden/controllers/dc.py\", line 200, in <module>\r\n  File \"/srv/web2py/gluon/globals.py\", line 421, in <lambda>\r\n    self._caller = lambda f: f()\r\n  File \"/srv/web2py/applications/eden/controllers/dc.py\", line 133, in target\r\n    return s3_rest_controller(rheader = s3db.dc_rheader,\r\n  File \"/srv/web2py/applications/eden/models/00_utils.py\", line 245, in s3_rest_controller\r\n    output = r(**attr)\r\n  File \"/srv/web2py/applications/eden/modules/s3/s3rest.py\", line 688, in __call__\r\n    output = handler(self, **attr)\r\n  File \"/srv/web2py/applications/eden/modules/s3/s3rest.py\", line 1775, in __call__\r\n    output = self.apply_method(r, **attr)\r\n  File \"/srv/web2py/applications/eden/modules/s3db/dc.py\", line 1565, in apply_method\r\n    output = self.html(r, title, **attr)\r\n  File \"/srv/web2py/applications/eden/modules/s3db/dc.py\", line 1771, in html\r\n    questions, stats = self._extract(r, **attr)\r\n  File \"/srv/web2py/applications/eden/modules/s3db/dc.py\", line 1679, in _extract\r\n    for posn in layout:\r\nTypeError: 'NoneType' object is not iterable\r\n```\r\n\r\n//Edit: Note that the traceback is also mentioned at the end of report in #1543, but without steps to reproduce and without the other 2 errors mentioned above, hence the separate issue.","performed_via_github_app":null,"score":1.0},{"url":"https://api.github.com/repos/web2py/py4web/issues/129","repository_url":"https://api.github.com/repos/web2py/py4web","labels_url":"https://api.github.com/repos/web2py/py4web/issues/129/labels{/name}","comments_url":"https://api.github.com/repos/web2py/py4web/issues/129/comments","events_url":"https://api.github.com/repos/web2py/py4web/issues/129/events","html_url":"https://github.com/web2py/py4web/issues/129","id":585541134,"node_id":"MDU6SXNzdWU1ODU1NDExMzQ=","number":129,"title":"Latest pydal master breaks dashboard reference fields","user":{"login":"misl6","id":8177736,"node_id":"MDQ6VXNlcjgxNzc3MzY=","avatar_url":"https://avatars0.githubusercontent.com/u/8177736?v=4","gravatar_id":"","url":"https://api.github.com/users/misl6","html_url":"https://github.com/misl6","followers_url":"https://api.github.com/users/misl6/followers","following_url":"https://api.github.com/users/misl6/following{/other_user}","gists_url":"https://api.github.com/users/misl6/gists{/gist_id}","starred_url":"https://api.github.com/users/misl6/starred{/owner}{/repo}","subscriptions_url":"https://api.github.com/users/misl6/subscriptions","organizations_url":"https://api.github.com/users/misl6/orgs","repos_url":"https://api.github.com/users/misl6/repos","events_url":"https://api.github.com/users/misl6/events{/privacy}","received_events_url":"https://api.github.com/users/misl6/received_events","type":"User","site_admin":false},"labels":[],"state":"closed","locked":false,"assignee":null,"assignees":[],"milestone":null,"comments":4,"created_at":"2020-03-21T17:19:45Z","updated_at":"2020-03-21T19:38:48Z","closed_at":"2020-03-21T18:51:14Z","author_association":"CONTRIBUTOR","active_lock_reason":null,"body":"Latest `pydal` master breaks `py4web` dashboard (reference fields).\r\n\r\nThis commit reverts a needed change: https://github.com/web2py/pydal/commit/202b55d5e9a4018e23950c60ea56e19324dd8fe0\r\n\r\n@mdipierro was just a cleanup or I missed something when I introduced this one?","performed_via_github_app":null,"score":1.0},{"url":"https://api.github.com/repos/web2py/py4web/issues/157","repository_url":"https://api.github.com/repos/web2py/py4web","labels_url":"https://api.github.com/repos/web2py/py4web/issues/157/labels{/name}","comments_url":"https://api.github.com/repos/web2py/py4web/issues/157/comments","events_url":"https://api.github.com/repos/web2py/py4web/issues/157/events","html_url":"https://github.com/web2py/py4web/issues/157","id":601521836,"node_id":"MDU6SXNzdWU2MDE1MjE4MzY=","number":157,"title":"Redis session setup in common.py","user":{"login":"mbelletti","id":493145,"node_id":"MDQ6VXNlcjQ5MzE0NQ==","avatar_url":"https://avatars3.githubusercontent.com/u/493145?v=4","gravatar_id":"","url":"https://api.github.com/users/mbelletti","html_url":"https://github.com/mbelletti","followers_url":"https://api.github.com/users/mbelletti/followers","following_url":"https://api.github.com/users/mbelletti/following{/other_user}","gists_url":"https://api.github.com/users/mbelletti/gists{/gist_id}","starred_url":"https://api.github.com/users/mbelletti/starred{/owner}{/repo}","subscriptions_url":"https://api.github.com/users/mbelletti/subscriptions","organizations_url":"https://api.github.com/users/mbelletti/orgs","repos_url":"https://api.github.com/users/mbelletti/repos","events_url":"https://api.github.com/users/mbelletti/events{/privacy}","received_events_url":"https://api.github.com/users/mbelletti/received_events","type":"User","site_admin":false},"labels":[],"state":"closed","locked":false,"assignee":null,"assignees":[],"milestone":null,"comments":0,"created_at":"2020-04-16T21:55:28Z","updated_at":"2020-04-18T21:59:05Z","closed_at":"2020-04-18T21:59:05Z","author_association":"CONTRIBUTOR","active_lock_reason":null,"body":"https://github.com/web2py/py4web/blob/533de1d8485a5e08d08a9213d019315d04c8060c/apps/_scaffold/common.py#L46\r\n\r\nas it is now it seems a typo and it return a tuple, but if I understand the intent correctly, when the key doesn't exists yet it will throw an error passing -2 to expire\r\nI think the correct behavior should be this one:\r\n```\r\nconn.set = lambda k, v, e, cs=conn.set, ct=conn.ttl: cs(k, v, e and ct(k)) if ct(k) >= 0 else cs(k, v, e) \r\n```\r\nor\r\n```\r\nconn.set = lambda k, v, e, cs=conn.set, ct=conn.ttl: cs(k, v, ct(k)) if ct(k) >= 0 else cs(k, v, e) \r\n```","performed_via_github_app":null,"score":1.0},{"url":"https://api.github.com/repos/web2py/py4web/issues/122","repository_url":"https://api.github.com/repos/web2py/py4web","labels_url":"https://api.github.com/repos/web2py/py4web/issues/122/labels{/name}","comments_url":"https://api.github.com/repos/web2py/py4web/issues/122/comments","events_url":"https://api.github.com/repos/web2py/py4web/issues/122/events","html_url":"https://github.com/web2py/py4web/issues/122","id":575716561,"node_id":"MDU6SXNzdWU1NzU3MTY1NjE=","number":122,"title":"http_accept vs content_type","user":{"login":"valq7711","id":11394363,"node_id":"MDQ6VXNlcjExMzk0MzYz","avatar_url":"https://avatars1.githubusercontent.com/u/11394363?v=4","gravatar_id":"","url":"https://api.github.com/users/valq7711","html_url":"https://github.com/valq7711","followers_url":"https://api.github.com/users/valq7711/followers","following_url":"https://api.github.com/users/valq7711/following{/other_user}","gists_url":"https://api.github.com/users/valq7711/gists{/gist_id}","starred_url":"https://api.github.com/users/valq7711/starred{/owner}{/repo}","subscriptions_url":"https://api.github.com/users/valq7711/subscriptions","organizations_url":"https://api.github.com/users/valq7711/orgs","repos_url":"https://api.github.com/users/valq7711/repos","events_url":"https://api.github.com/users/valq7711/events{/privacy}","received_events_url":"https://api.github.com/users/valq7711/received_events","type":"User","site_admin":false},"labels":[],"state":"closed","locked":false,"assignee":null,"assignees":[],"milestone":null,"comments":0,"created_at":"2020-03-04T19:49:21Z","updated_at":"2020-03-18T16:16:17Z","closed_at":"2020-03-18T16:16:17Z","author_association":"CONTRIBUTOR","active_lock_reason":null,"body":"https://github.com/web2py/py4web/blob/175cbe49539baa9db304868f5e1ab2525e83d707/py4web/utils/auth.py#L35-L40\r\n\r\nI think that in this case it is incorrect to use `content_type`, because it specifies the type of data sent by the client, but not the type of expected response.\r\nI think we should check `request.headers['accept']`  - like:\r\n```python\r\n   if re.search( '(^|\\s|,)application/json(,|\\s|$)', request.headers['accept'])\r\n```","performed_via_github_app":null,"score":1.0},{"url":"https://api.github.com/repos/WorldHealthOrganization/app/issues/10","repository_url":"https://api.github.com/repos/WorldHealthOrganization/app","labels_url":"https://api.github.com/repos/WorldHealthOrganization/app/issues/10/labels{/name}","comments_url":"https://api.github.com/repos/WorldHealthOrganization/app/issues/10/comments","events_url":"https://api.github.com/repos/WorldHealthOrganization/app/issues/10/events","html_url":"https://github.com/WorldHealthOrganization/app/issues/10","id":583998096,"node_id":"MDU6SXNzdWU1ODM5OTgwOTY=","number":10,"title":"CLAs","user":{"login":"advayDev1","id":11729521,"node_id":"MDQ6VXNlcjExNzI5NTIx","avatar_url":"https://avatars3.githubusercontent.com/u/11729521?v=4","gravatar_id":"","url":"https://api.github.com/users/advayDev1","html_url":"https://github.com/advayDev1","followers_url":"https://api.github.com/users/advayDev1/followers","following_url":"https://api.github.com/users/advayDev1/following{/other_user}","gists_url":"https://api.github.com/users/advayDev1/gists{/gist_id}","starred_url":"https://api.github.com/users/advayDev1/starred{/owner}{/repo}","subscriptions_url":"https://api.github.com/users/advayDev1/subscriptions","organizations_url":"https://api.github.com/users/advayDev1/orgs","repos_url":"https://api.github.com/users/advayDev1/repos","events_url":"https://api.github.com/users/advayDev1/events{/privacy}","received_events_url":"https://api.github.com/users/advayDev1/received_events","type":"User","site_admin":false},"labels":[{"id":1921695645,"node_id":"MDU6TGFiZWwxOTIxNjk1NjQ1","url":"https://api.github.com/repos/WorldHealthOrganization/app/labels/a:legal","name":"a:legal","color":"fef2c0","default":false,"description":"Legal tasks"}],"state":"closed","locked":false,"assignee":{"login":"brunobowden","id":679339,"node_id":"MDQ6VXNlcjY3OTMzOQ==","avatar_url":"https://avatars0.githubusercontent.com/u/679339?v=4","gravatar_id":"","url":"https://api.github.com/users/brunobowden","html_url":"https://github.com/brunobowden","followers_url":"https://api.github.com/users/brunobowden/followers","following_url":"https://api.github.com/users/brunobowden/following{/other_user}","gists_url":"https://api.github.com/users/brunobowden/gists{/gist_id}","starred_url":"https://api.github.com/users/brunobowden/starred{/owner}{/repo}","subscriptions_url":"https://api.github.com/users/brunobowden/subscriptions","organizations_url":"https://api.github.com/users/brunobowden/orgs","repos_url":"https://api.github.com/users/brunobowden/repos","events_url":"https://api.github.com/users/brunobowden/events{/privacy}","received_events_url":"https://api.github.com/users/brunobowden/received_events","type":"User","site_admin":false},"assignees":[{"login":"brunobowden","id":679339,"node_id":"MDQ6VXNlcjY3OTMzOQ==","avatar_url":"https://avatars0.githubusercontent.com/u/679339?v=4","gravatar_id":"","url":"https://api.github.com/users/brunobowden","html_url":"https://github.com/brunobowden","followers_url":"https://api.github.com/users/brunobowden/followers","following_url":"https://api.github.com/users/brunobowden/following{/other_user}","gists_url":"https://api.github.com/users/brunobowden/gists{/gist_id}","starred_url":"https://api.github.com/users/brunobowden/starred{/owner}{/repo}","subscriptions_url":"https://api.github.com/users/brunobowden/subscriptions","organizations_url":"https://api.github.com/users/brunobowden/orgs","repos_url":"https://api.github.com/users/brunobowden/repos","events_url":"https://api.github.com/users/brunobowden/events{/privacy}","received_events_url":"https://api.github.com/users/brunobowden/received_events","type":"User","site_admin":false}],"milestone":null,"comments":6,"created_at":"2020-03-18T20:57:23Z","updated_at":"2020-04-04T22:21:01Z","closed_at":"2020-04-04T22:21:01Z","author_association":"MEMBER","active_lock_reason":null,"body":"I know we're operating very fast here possibly without formal CLAs, so I'm just going to leave this here.  It's not legal advice to anyone else.\r\n\r\nI, Advay Mengle, license all of my original software contributions in this repository to the World Health Organization and to the public at large, under the terms of the MIT License:\r\n\r\n````\r\nMIT License\r\n\r\nCopyright (c) 2020 Advay Mengle\r\n\r\nPermission is hereby granted, free of charge, to any person obtaining a copy\r\nof this software and associated documentation files (the \"Software\"), to deal\r\nin the Software without restriction, including without limitation the rights\r\nto use, copy, modify, merge, publish, distribute, sublicense, and/or sell\r\ncopies of the Software, and to permit persons to whom the Software is\r\nfurnished to do so, subject to the following conditions:\r\n\r\nThe above copyright notice and this permission notice shall be included in all\r\ncopies or substantial portions of the Software.\r\n\r\nTHE SOFTWARE IS PROVIDED \"AS IS\", WITHOUT WARRANTY OF ANY KIND, EXPRESS OR\r\nIMPLIED, INCLUDING BUT NOT LIMITED TO THE WARRANTIES OF MERCHANTABILITY,\r\nFITNESS FOR A PARTICULAR PURPOSE AND NONINFRINGEMENT. IN NO EVENT SHALL THE\r\nAUTHORS OR COPYRIGHT HOLDERS BE LIABLE FOR ANY CLAIM, DAMAGES OR OTHER\r\nLIABILITY, WHETHER IN AN ACTION OF CONTRACT, TORT OR OTHERWISE, ARISING FROM,\r\nOUT OF OR IN CONNECTION WITH THE SOFTWARE OR THE USE OR OTHER DEALINGS IN THE\r\nSOFTWARE.\r\n````","performed_via_github_app":null,"score":1.0},{"url":"https://api.github.com/repos/nicozanf/py4web-pyinstaller/issues/1","repository_url":"https://api.github.com/repos/nicozanf/py4web-pyinstaller","labels_url":"https://api.github.com/repos/nicozanf/py4web-pyinstaller/issues/1/labels{/name}","comments_url":"https://api.github.com/repos/nicozanf/py4web-pyinstaller/issues/1/comments","events_url":"https://api.github.com/repos/nicozanf/py4web-pyinstaller/issues/1/events","html_url":"https://github.com/nicozanf/py4web-pyinstaller/issues/1","id":593616103,"node_id":"MDU6SXNzdWU1OTM2MTYxMDM=","number":1,"title":"include standalone python3.exe ","user":{"login":"valq7711","id":11394363,"node_id":"MDQ6VXNlcjExMzk0MzYz","avatar_url":"https://avatars1.githubusercontent.com/u/11394363?v=4","gravatar_id":"","url":"https://api.github.com/users/valq7711","html_url":"https://github.com/valq7711","followers_url":"https://api.github.com/users/valq7711/followers","following_url":"https://api.github.com/users/valq7711/following{/other_user}","gists_url":"https://api.github.com/users/valq7711/gists{/gist_id}","starred_url":"https://api.github.com/users/valq7711/starred{/owner}{/repo}","subscriptions_url":"https://api.github.com/users/valq7711/subscriptions","organizations_url":"https://api.github.com/users/valq7711/orgs","repos_url":"https://api.github.com/users/valq7711/repos","events_url":"https://api.github.com/users/valq7711/events{/privacy}","received_events_url":"https://api.github.com/users/valq7711/received_events","type":"User","site_admin":false},"labels":[],"state":"closed","locked":false,"assignee":null,"assignees":[],"milestone":null,"comments":5,"created_at":"2020-04-03T20:15:16Z","updated_at":"2020-04-05T22:50:48Z","closed_at":"2020-04-05T22:05:02Z","author_association":"NONE","active_lock_reason":null,"body":"Hello Nico!\r\nThanks for your work! It is very useful!\r\nCould you also include standalone `python3.exe` (or `py.exe`) similar to web2py binaries?\r\nThank you in advance!\r\n","performed_via_github_app":null,"score":1.0},{"url":"https://api.github.com/repos/sahana/eden/issues/1543","repository_url":"https://api.github.com/repos/sahana/eden","labels_url":"https://api.github.com/repos/sahana/eden/issues/1543/labels{/name}","comments_url":"https://api.github.com/repos/sahana/eden/issues/1543/comments","events_url":"https://api.github.com/repos/sahana/eden/issues/1543/events","html_url":"https://github.com/sahana/eden/issues/1543","id":602520940,"node_id":"MDU6SXNzdWU2MDI1MjA5NDA=","number":1543,"title":"Several various NoneType errors (setup, vol, project, inv, dc, ...)","user":{"login":"trendspotter","id":15286128,"node_id":"MDQ6VXNlcjE1Mjg2MTI4","avatar_url":"https://avatars1.githubusercontent.com/u/15286128?v=4","gravatar_id":"","url":"https://api.github.com/users/trendspotter","html_url":"https://github.com/trendspotter","followers_url":"https://api.github.com/users/trendspotter/followers","following_url":"https://api.github.com/users/trendspotter/following{/other_user}","gists_url":"https://api.github.com/users/trendspotter/gists{/gist_id}","starred_url":"https://api.github.com/users/trendspotter/starred{/owner}{/repo}","subscriptions_url":"https://api.github.com/users/trendspotter/subscriptions","organizations_url":"https://api.github.com/users/trendspotter/orgs","repos_url":"https://api.github.com/users/trendspotter/repos","events_url":"https://api.github.com/users/trendspotter/events{/privacy}","received_events_url":"https://api.github.com/users/trendspotter/received_events","type":"User","site_admin":false},"labels":[],"state":"closed","locked":false,"assignee":null,"assignees":[],"milestone":null,"comments":10,"created_at":"2020-04-18T18:25:41Z","updated_at":"2020-04-21T14:07:15Z","closed_at":"2020-04-21T13:40:26Z","author_association":"CONTRIBUTOR","active_lock_reason":null,"body":"We're encoutnering a suspiciously high number of failures where a variable of a specific type is expected but it turns out to be `None`. I haven't investigated the possible causes yet, but it almost looks like there may be common cause for them.\r\n\r\nAll of the following scenarios are done on\r\n - default template with demo data\r\n - python 3.8.2\r\n - Web2py R-2.18.5 (59700b8) with compat patch from eden_deploy\r\n\r\n### Scenario 1 - Setup configuration wizard\r\nSteps to reproduce:\r\n1. Log in, go to *Setup* in *Administration* menu\r\n2. Without even changing anything, click on *Submit*.\r\n\r\n```\r\nTraceback (most recent call last):\r\n  File \"/srv/web2py/gluon/restricted.py\", line 219, in restricted\r\n    exec(ccode, environment)\r\n  File \"/srv/web2py/applications/eden/controllers/setup.py\", line 776, in <module>\r\n  File \"/srv/web2py/gluon/globals.py\", line 421, in <lambda>\r\n    self._caller = lambda f: f()\r\n  File \"/srv/web2py/applications/eden/controllers/setup.py\", line 545, in deployment\r\n    return s3_rest_controller(rheader = s3db.setup_rheader,\r\n  File \"/srv/web2py/applications/eden/models/00_utils.py\", line 245, in s3_rest_controller\r\n    output = r(**attr)\r\n  File \"/srv/web2py/applications/eden/modules/s3/s3rest.py\", line 688, in __call__\r\n    output = handler(self, **attr)\r\n  File \"/srv/web2py/applications/eden/modules/s3db/setup.py\", line 1935, in setup_instance_wizard\r\n    result = setup_modules_apply(r.id, form.vars)\r\n  File \"/srv/web2py/applications/eden/modules/s3db/setup.py\", line 4671, in setup_modules_apply\r\n    task_vars[\"instance_id\"] = instance_id # To Upload Logs to Instance record\r\nTypeError: 'NoneType' object does not support item assignment\r\n```\r\n\r\n### Scenario 2 - Volunteer service record\r\nSteps to reproduce:\r\n1. Log in, create organization if none exists yet\r\n2. Go to *Volunteers* -> *Course Catalog* -> *Create*\r\n3. Create a new course, fill in mandatory fields (name) and *Save*\r\n4. Go to *Volunteers* -> *Volunteers* -> *Create*\r\n5. Fill in the mandatory fields (org, name) and *Save*\r\n6. Go to *Trainings* tab, add training created in step 3 and *Save*\r\n7. Click on volunteer's *Service Record*\r\n\r\n```\r\nTraceback (most recent call last):\r\n  File \"/srv/web2py/gluon/restricted.py\", line 219, in restricted\r\n    exec(ccode, environment)\r\n  File \"/srv/web2py/applications/eden/controllers/vol.py\", line 527, in <module>\r\n  File \"/srv/web2py/gluon/globals.py\", line 421, in <lambda>\r\n    self._caller = lambda f: f()\r\n  File \"/srv/web2py/applications/eden/controllers/vol.py\", line 46, in human_resource\r\n    return s3db.hrm_human_resource_controller()\r\n  File \"/srv/web2py/applications/eden/modules/s3db/hrm.py\", line 8288, in hrm_human_resource_controller\r\n    return current.rest_controller(\"hrm\", \"human_resource\")\r\n  File \"/srv/web2py/applications/eden/models/00_utils.py\", line 245, in s3_rest_controller\r\n    output = r(**attr)\r\n  File \"/srv/web2py/applications/eden/modules/s3/s3rest.py\", line 688, in __call__\r\n    output = handler(self, **attr)\r\n  File \"/srv/web2py/applications/eden/modules/s3db/vol.py\", line 1297, in vol_service_record\r\n    return exporter(r.resource,\r\n  File \"/srv/web2py/applications/eden/modules/s3/s3export.py\", line 220, in pdf\r\n    return codec(*args, **kwargs)\r\n  File \"/srv/web2py/applications/eden/modules/s3/codecs/pdf.py\", line 303, in encode\r\n    body_flowable = self.get_html_flowable(callback(r),\r\n  File \"/srv/web2py/applications/eden/modules/s3db/vol.py\", line 1120, in callback\r\n    hours[_date.date()] = {\"course\": row[\"hrm_course\"].name,\r\nAttributeError: 'NoneType' object has no attribute 'date'\r\n```\r\n\r\n### Scenario 3 - Project summary report\r\nSteps to reproduce:\r\n1. Log in, create organization if none exists yet\r\n2. Go to *Projects* -> *Projects* -> *Create*\r\n3. Create a new project, fill in mandatory fields (org, name) and *Save*\r\n4. Open the project, go to *Indicators* tab\r\n5. Create a new indicator, fill in code and *Save*\r\n6. Click on *Project summary report*, then *Generate PDF*\r\n\r\n```\r\nTraceback (most recent call last):\r\n  File \"/srv/web2py/gluon/restricted.py\", line 219, in restricted\r\n    exec(ccode, environment)\r\n  File \"/srv/web2py/applications/eden/controllers/project.py\", line 1492, in <module>\r\n  File \"/srv/web2py/gluon/globals.py\", line 421, in <lambda>\r\n    self._caller = lambda f: f()\r\n  File \"/srv/web2py/applications/eden/controllers/project.py\", line 492, in project\r\n    return s3_rest_controller(module, \"project\",\r\n  File \"/srv/web2py/applications/eden/models/00_utils.py\", line 245, in s3_rest_controller\r\n    output = r(**attr)\r\n  File \"/srv/web2py/applications/eden/modules/s3/s3rest.py\", line 688, in __call__\r\n    output = handler(self, **attr)\r\n  File \"/srv/web2py/applications/eden/modules/s3/s3rest.py\", line 1775, in __call__\r\n    output = self.apply_method(r, **attr)\r\n  File \"/srv/web2py/applications/eden/modules/s3db/project.py\", line 7139, in apply_method\r\n    output = self.pdf(r, **attr)\r\n  File \"/srv/web2py/applications/eden/modules/s3db/project.py\", line 8346, in pdf\r\n    project, goals = self._extract(r, **attr)\r\n  File \"/srv/web2py/applications/eden/modules/s3db/project.py\", line 7347, in _extract\r\n    goals[goal_id][\"outcomes\"][outcome_id][\"outputs\"][output_id][\"indicators\"][indicator_id] = {\"code\" : row.code,\r\nKeyError: None\r\n```\r\n\r\n### Scenario 4 - Warehouse reports\r\nSteps to reproduce:\r\n1. Log in\r\n2. Go to *Warehouses* -> *Warehouses* -> *Create*\r\n3. Create a new warehouse, fill in mandatory fields (name) and *Save*\r\n4. Go to *Warehouses* -> *Received/Incoming shipments* -> *Create*\r\n5. Create a new shipment, fill in mandatory fields (warehouse, type) and *Save*\r\n6. Click *Add item to shipment*\r\n7. Add item to shipment, fill in mandatory fields (item - e.g. ventilator, qty) and *Save*\r\n8. Click on *Report* -> *Utilization report*\r\n\r\n```\r\nTraceback (most recent call last):\r\n  File \"/srv/web2py/gluon/restricted.py\", line 219, in restricted\r\n    exec(ccode, environment)\r\n  File \"/srv/web2py/applications/eden/controllers/inv.py\", line 1785, in <module>\r\n  File \"/srv/web2py/gluon/globals.py\", line 421, in <lambda>\r\n    self._caller = lambda f: f()\r\n  File \"/srv/web2py/applications/eden/controllers/inv.py\", line 1498, in track_item\r\n    output = s3_rest_controller(rheader = s3db.inv_rheader,\r\n  File \"/srv/web2py/applications/eden/models/00_utils.py\", line 245, in s3_rest_controller\r\n    output = r(**attr)\r\n  File \"/srv/web2py/applications/eden/modules/s3/s3rest.py\", line 691, in __call__\r\n    output = self.resource.crud(self, **attr)\r\n  File \"/srv/web2py/applications/eden/modules/s3/s3rest.py\", line 1775, in __call__\r\n    output = self.apply_method(r, **attr)\r\n  File \"/srv/web2py/applications/eden/modules/s3/s3crud.py\", line 113, in apply_method\r\n    output = self.select(r, **attr)\r\n  File \"/srv/web2py/applications/eden/modules/s3/s3crud.py\", line 1204, in select\r\n    output = self._datatable(r, **attr)\r\n  File \"/srv/web2py/applications/eden/modules/s3/s3crud.py\", line 1517, in _datatable\r\n    dt, totalrows = resource.datatable(fields = list_fields,\r\n  File \"/srv/web2py/applications/eden/modules/s3/s3resource.py\", line 924, in datatable\r\n    data = self.select(selectors,\r\n  File \"/srv/web2py/applications/eden/modules/s3/s3resource.py\", line 516, in select\r\n    data = S3ResourceData(self,\r\n  File \"/srv/web2py/applications/eden/modules/s3/s3resource.py\", line 5749, in __init__\r\n    records = self.extract(rows,\r\n  File \"/srv/web2py/applications/eden/modules/s3/s3resource.py\", line 6344, in extract\r\n    value = value()\r\n  File \"/srv/web2py/gluon/packages/dal/pydal/objects.py\", line 2554, in __call__\r\n    return self.method(self.row, *args, **kwargs)\r\n  File \"/srv/web2py/applications/eden/modules/s3db/inv.py\", line 1951, in inv_track_item_total_value\r\n    v = row.quantity * row.pack_value\r\nTypeError: unsupported operand type(s) for *: 'float' and 'NoneType'\r\n```\r\n\r\nThere are several more scenarios which fail in similar fashion (NoneType related) for which we didn't test the minimal steps to reproduce yet, as there may be common fix for them all.\r\n\r\nE.g. Assessment response creation in dc module fails with\r\n```\r\nTraceback (most recent call last):\r\n  File \"/srv/web2py/gluon/restricted.py\", line 219, in restricted\r\n    exec(ccode, environment)\r\n  File \"/srv/web2py/applications/eden/controllers/dc.py\", line 200, in <module>\r\n  File \"/srv/web2py/gluon/globals.py\", line 421, in <lambda>\r\n    self._caller = lambda f: f()\r\n  File \"/srv/web2py/applications/eden/controllers/dc.py\", line 194, in respnse\r\n    return s3_rest_controller(\"dc\", \"response\",\r\n  File \"/srv/web2py/applications/eden/models/00_utils.py\", line 245, in s3_rest_controller\r\n    output = r(**attr)\r\n  File \"/srv/web2py/applications/eden/modules/s3/s3rest.py\", line 629, in __call__\r\n    pre = preprocess(self)\r\n  File \"/srv/web2py/applications/eden/controllers/dc.py\", line 189, in prep\r\n    s3db.dc_answer_form(r, tablename)\r\n  File \"/srv/web2py/applications/eden/modules/s3db/dc.py\", line 1402, in dc_answer_form\r\n    for posn in layout:\r\nTypeError: 'NoneType' object is not iterable\r\n```\r\nand so on...\r\n\r\nIf they don't have common cause and you'd like to have a separate issues for them, I'd be happy to split them.","performed_via_github_app":null,"score":1.0},{"url":"https://api.github.com/repos/web2py/pydal/issues/609","repository_url":"https://api.github.com/repos/web2py/pydal","labels_url":"https://api.github.com/repos/web2py/pydal/issues/609/labels{/name}","comments_url":"https://api.github.com/repos/web2py/pydal/issues/609/comments","events_url":"https://api.github.com/repos/web2py/pydal/issues/609/events","html_url":"https://github.com/web2py/pydal/issues/609","id":566513345,"node_id":"MDU6SXNzdWU1NjY1MTMzNDU=","number":609,"title":"IS_DATETIME validator throws exception on bad input","user":{"login":"crc1021","id":6224689,"node_id":"MDQ6VXNlcjYyMjQ2ODk=","avatar_url":"https://avatars3.githubusercontent.com/u/6224689?v=4","gravatar_id":"","url":"https://api.github.com/users/crc1021","html_url":"https://github.com/crc1021","followers_url":"https://api.github.com/users/crc1021/followers","following_url":"https://api.github.com/users/crc1021/following{/other_user}","gists_url":"https://api.github.com/users/crc1021/gists{/gist_id}","starred_url":"https://api.github.com/users/crc1021/starred{/owner}{/repo}","subscriptions_url":"https://api.github.com/users/crc1021/subscriptions","organizations_url":"https://api.github.com/users/crc1021/orgs","repos_url":"https://api.github.com/users/crc1021/repos","events_url":"https://api.github.com/users/crc1021/events{/privacy}","received_events_url":"https://api.github.com/users/crc1021/received_events","type":"User","site_admin":false},"labels":[],"state":"closed","locked":false,"assignee":null,"assignees":[],"milestone":null,"comments":1,"created_at":"2020-02-17T20:56:15Z","updated_at":"2020-02-18T13:33:33Z","closed_at":"2020-02-18T13:33:33Z","author_association":"NONE","active_lock_reason":null,"body":"In py4web, I have a datetime field:  Field('start', 'datetime', label='Start Time', notnull=True)\r\nIf the value in the form field is not valid when the form is submitted, py4web throws an exception because of the formatter method in the IS_DATETIME validator\r\n```Traceback (most recent call last):\r\n  File \"/home/eric/.local/lib/python3.7/site-packages/py4web/core.py\", line 546, in wrapper\r\n    ret = func(*func_args, **func_kwargs)\r\n  File \"/home/eric/.local/lib/python3.7/site-packages/py4web/core.py\", line 509, in wrapper\r\n    ret = obj.transform(ret)\r\n  File \"/home/eric/.local/lib/python3.7/site-packages/py4web/core.py\", line 300, in transform\r\n    reader=Template.reader,\r\n  File \"/home/eric/.local/lib/python3.7/site-packages/yatl/template.py\", line 968, in render\r\n    exec(code, context)\r\n  File \"<string>\", line 25, in <module>\r\n  File \"/home/eric/.local/lib/python3.7/site-packages/yatl/template.py\", line 831, in write\r\n    data = data.xml()\r\n  File \"/home/eric/.local/lib/python3.7/site-packages/py4web/utils/form.py\", line 300, in xml\r\n    return self.helper().xml()\r\n  File \"/home/eric/.local/lib/python3.7/site-packages/py4web/utils/form.py\", line 288, in helper\r\n    self.table, self.vars, self.errors, self.readonly, self.deletable\r\n  File \"/home/eric/.local/lib/python3.7/site-packages/py4web/utils/form.py\", line 150, in FormStyleBulma\r\n    return FormStyleDefault(table, vars, errors, readonly, deletable, classes)\r\n  File \"/home/eric/.local/lib/python3.7/site-packages/py4web/utils/form.py\", line 34, in FormStyleDefault\r\n    value = field.formatter(vars.get(field.name))\r\n  File \"/home/eric/.local/lib/python3.7/site-packages/pydal/objects.py\", line 2161, in formatter\r\n    value = item.formatter(value)\r\n  File \"/home/eric/.local/lib/python3.7/site-packages/pydal/validators.py\", line 3796, in formatter\r\n    year = value.year\r\nAttributeError: 'str' object has no attribute 'year'\r\n```","performed_via_github_app":null,"score":1.0},{"url":"https://api.github.com/repos/web2py/py4web/issues/108","repository_url":"https://api.github.com/repos/web2py/py4web","labels_url":"https://api.github.com/repos/web2py/py4web/issues/108/labels{/name}","comments_url":"https://api.github.com/repos/web2py/py4web/issues/108/comments","events_url":"https://api.github.com/repos/web2py/py4web/issues/108/events","html_url":"https://github.com/web2py/py4web/issues/108","id":562163397,"node_id":"MDU6SXNzdWU1NjIxNjMzOTc=","number":108,"title":"Each worker has own session?","user":{"login":"valq7711","id":11394363,"node_id":"MDQ6VXNlcjExMzk0MzYz","avatar_url":"https://avatars1.githubusercontent.com/u/11394363?v=4","gravatar_id":"","url":"https://api.github.com/users/valq7711","html_url":"https://github.com/valq7711","followers_url":"https://api.github.com/users/valq7711/followers","following_url":"https://api.github.com/users/valq7711/following{/other_user}","gists_url":"https://api.github.com/users/valq7711/gists{/gist_id}","starred_url":"https://api.github.com/users/valq7711/starred{/owner}{/repo}","subscriptions_url":"https://api.github.com/users/valq7711/subscriptions","organizations_url":"https://api.github.com/users/valq7711/orgs","repos_url":"https://api.github.com/users/valq7711/repos","events_url":"https://api.github.com/users/valq7711/events{/privacy}","received_events_url":"https://api.github.com/users/valq7711/received_events","type":"User","site_admin":false},"labels":[],"state":"closed","locked":false,"assignee":null,"assignees":[],"milestone":null,"comments":1,"created_at":"2020-02-09T11:39:56Z","updated_at":"2020-02-10T15:40:56Z","closed_at":"2020-02-10T15:40:56Z","author_association":"CONTRIBUTOR","active_lock_reason":null,"body":"https://github.com/web2py/py4web/blob/830c76a2222d0a62a37bea8a5bdbfd9bbb5ddda4/py4web/core.py#L331\r\n\r\nIn case of usage multiple workers, each worker will have its own secret  i.e. own session! (If `secret`-argument is not provided).\r\nI got this issue on gunicorn with gevent workers. \r\nCould we store `uuid` key in `os.environ` to share secret between workers? \r\n\r\nUPDATE:\r\nAs variant, we can store in os.environ only the flag like `secret_is_generated`, if it is not set then uuid-secret should be generated and stored in some file, otherwise, the `secret` should be read from that file.\r\n  ","performed_via_github_app":null,"score":1.0},{"url":"https://api.github.com/repos/sahana/eden/issues/1468","repository_url":"https://api.github.com/repos/sahana/eden","labels_url":"https://api.github.com/repos/sahana/eden/issues/1468/labels{/name}","comments_url":"https://api.github.com/repos/sahana/eden/issues/1468/comments","events_url":"https://api.github.com/repos/sahana/eden/issues/1468/events","html_url":"https://github.com/sahana/eden/issues/1468","id":298528599,"node_id":"MDU6SXNzdWUyOTg1Mjg1OTk=","number":1468,"title":"Translation export fails when \"Select all templates\" is used","user":{"login":"trendspotter","id":15286128,"node_id":"MDQ6VXNlcjE1Mjg2MTI4","avatar_url":"https://avatars1.githubusercontent.com/u/15286128?v=4","gravatar_id":"","url":"https://api.github.com/users/trendspotter","html_url":"https://github.com/trendspotter","followers_url":"https://api.github.com/users/trendspotter/followers","following_url":"https://api.github.com/users/trendspotter/following{/other_user}","gists_url":"https://api.github.com/users/trendspotter/gists{/gist_id}","starred_url":"https://api.github.com/users/trendspotter/starred{/owner}{/repo}","subscriptions_url":"https://api.github.com/users/trendspotter/subscriptions","organizations_url":"https://api.github.com/users/trendspotter/orgs","repos_url":"https://api.github.com/users/trendspotter/repos","events_url":"https://api.github.com/users/trendspotter/events{/privacy}","received_events_url":"https://api.github.com/users/trendspotter/received_events","type":"User","site_admin":false},"labels":[{"id":337203244,"node_id":"MDU6TGFiZWwzMzcyMDMyNDQ=","url":"https://api.github.com/repos/sahana/eden/labels/Admin","name":"Admin","color":"eb6420","default":false,"description":null},{"id":337201926,"node_id":"MDU6TGFiZWwzMzcyMDE5MjY=","url":"https://api.github.com/repos/sahana/eden/labels/Bug","name":"Bug","color":"fbca04","default":false,"description":null},{"id":336396218,"node_id":"MDU6TGFiZWwzMzYzOTYyMTg=","url":"https://api.github.com/repos/sahana/eden/labels/Minor","name":"Minor","color":"e11d21","default":false,"description":null}],"state":"closed","locked":false,"assignee":null,"assignees":[],"milestone":null,"comments":26,"created_at":"2018-02-20T09:46:27Z","updated_at":"2020-02-10T14:59:18Z","closed_at":"2020-02-10T14:59:17Z","author_association":"CONTRIBUTOR","active_lock_reason":null,"body":"Steps to reproduce:\r\n1. Go to `/eden/admin/translate/create`\r\n2. Check the *Select all templates (All modules included)* checkbox\r\n3. Enter a new language code (eg. *xx*)\r\n4. Click *Submit*\r\n\r\nExpected result:\r\nXLS file with translation strings will be offered for download.\r\n\r\nActual result:\r\nError 500 + following traceback\r\n```\r\nTraceback (most recent call last):\r\n  File \"/srv/web2py/gluon/restricted.py\", line 219, in restricted\r\n    exec(ccode, environment)\r\n  File \"/srv/web2py/applications/eden/controllers/admin.py\", line 1164, in <module>\r\n  File \"/srv/web2py/gluon/globals.py\", line 419, in <lambda>\r\n    self._caller = lambda f: f()\r\n  File \"/srv/web2py/applications/eden/controllers/admin.py\", line 1087, in translate\r\n    output = s3_rest_controller(\"translate\", \"language\")\r\n  File \"/srv/web2py/applications/eden/models/00_utils.py\", line 243, in s3_rest_controller\r\n    output = r(**attr)\r\n  File \"applications/eden/modules/s3/s3rest.py\", line 693, in __call__\r\n    output = postprocess(self, output)\r\n  File \"/srv/web2py/applications/eden/controllers/admin.py\", line 851, in postp\r\n    output = X.export_file(code, modlist, [], filetype, all_template_flag)\r\n  File \"applications/eden/modules/s3/s3translate.py\", line 1112, in export_file\r\n    return self.write_xls(Strings, langcode)\r\n  File \"applications/eden/modules/s3/s3translate.py\", line 1290, in write_xls\r\n    wbk.save(output)\r\n  File \"/usr/lib/python2.7/site-packages/xlwt/Workbook.py\", line 710, in save\r\n    doc.save(filename_or_stream, self.get_biff_data())\r\n  File \"/usr/lib/python2.7/site-packages/xlwt/Workbook.py\", line 674, in get_biff_data\r\n    shared_str_table   = self.__sst_rec()\r\n  File \"/usr/lib/python2.7/site-packages/xlwt/Workbook.py\", line 636, in __sst_rec\r\n    return self.__sst.get_biff_record()\r\n  File \"/usr/lib/python2.7/site-packages/xlwt/BIFFRecords.py\", line 77, in get_biff_record\r\n    self._add_to_sst(s)\r\n  File \"/usr/lib/python2.7/site-packages/xlwt/BIFFRecords.py\", line 92, in _add_to_sst\r\n    u_str = upack2(s, self.encoding)\r\n  File \"/usr/lib/python2.7/site-packages/xlwt/UnicodeUtils.py\", line 55, in upack2\r\n    raise Exception('String longer than 32767 characters')\r\nException: String longer than 32767 characters\r\n```\r\n\r\nExamining the XLS during creation shows that there is some weird recursion at play which causes the export to repeat the string location and eventually hits the character limit given by *xlwt*.","performed_via_github_app":null,"score":1.0},{"url":"https://api.github.com/repos/emmett-framework/emmett/issues/25","repository_url":"https://api.github.com/repos/emmett-framework/emmett","labels_url":"https://api.github.com/repos/emmett-framework/emmett/issues/25/labels{/name}","comments_url":"https://api.github.com/repos/emmett-framework/emmett/issues/25/comments","events_url":"https://api.github.com/repos/emmett-framework/emmett/issues/25/events","html_url":"https://github.com/emmett-framework/emmett/issues/25","id":59078705,"node_id":"MDU6SXNzdWU1OTA3ODcwNQ==","number":25,"title":"sdict may need an update","user":{"login":"gi0baro","id":5019985,"node_id":"MDQ6VXNlcjUwMTk5ODU=","avatar_url":"https://avatars3.githubusercontent.com/u/5019985?v=4","gravatar_id":"","url":"https://api.github.com/users/gi0baro","html_url":"https://github.com/gi0baro","followers_url":"https://api.github.com/users/gi0baro/followers","following_url":"https://api.github.com/users/gi0baro/following{/other_user}","gists_url":"https://api.github.com/users/gi0baro/gists{/gist_id}","starred_url":"https://api.github.com/users/gi0baro/starred{/owner}{/repo}","subscriptions_url":"https://api.github.com/users/gi0baro/subscriptions","organizations_url":"https://api.github.com/users/gi0baro/orgs","repos_url":"https://api.github.com/users/gi0baro/repos","events_url":"https://api.github.com/users/gi0baro/events{/privacy}","received_events_url":"https://api.github.com/users/gi0baro/received_events","type":"User","site_admin":false},"labels":[],"state":"closed","locked":false,"assignee":null,"assignees":[],"milestone":null,"comments":1,"created_at":"2015-02-26T14:19:03Z","updated_at":"2019-11-22T17:56:07Z","closed_at":"2019-11-22T17:56:07Z","author_association":"MEMBER","active_lock_reason":null,"body":"Inspect https://github.com/web2py/web2py/commit/d6c565f33f39e94cf87a21bbd0948983fcbfd21e\n","performed_via_github_app":null,"score":1.0},{"url":"https://api.github.com/repos/davidhalter/jedi-vim/issues/298","repository_url":"https://api.github.com/repos/davidhalter/jedi-vim","labels_url":"https://api.github.com/repos/davidhalter/jedi-vim/issues/298/labels{/name}","comments_url":"https://api.github.com/repos/davidhalter/jedi-vim/issues/298/comments","events_url":"https://api.github.com/repos/davidhalter/jedi-vim/issues/298/events","html_url":"https://github.com/davidhalter/jedi-vim/issues/298","id":39844555,"node_id":"MDU6SXNzdWUzOTg0NDU1NQ==","number":298,"title":"Autocomplete Django Models","user":{"login":"lebster","id":914433,"node_id":"MDQ6VXNlcjkxNDQzMw==","avatar_url":"https://avatars1.githubusercontent.com/u/914433?v=4","gravatar_id":"","url":"https://api.github.com/users/lebster","html_url":"https://github.com/lebster","followers_url":"https://api.github.com/users/lebster/followers","following_url":"https://api.github.com/users/lebster/following{/other_user}","gists_url":"https://api.github.com/users/lebster/gists{/gist_id}","starred_url":"https://api.github.com/users/lebster/starred{/owner}{/repo}","subscriptions_url":"https://api.github.com/users/lebster/subscriptions","organizations_url":"https://api.github.com/users/lebster/orgs","repos_url":"https://api.github.com/users/lebster/repos","events_url":"https://api.github.com/users/lebster/events{/privacy}","received_events_url":"https://api.github.com/users/lebster/received_events","type":"User","site_admin":false},"labels":[{"id":114180220,"node_id":"MDU6TGFiZWwxMTQxODAyMjA=","url":"https://api.github.com/repos/davidhalter/jedi-vim/labels/jedi-issue","name":"jedi-issue","color":"fb6420","default":false,"description":null}],"state":"closed","locked":false,"assignee":null,"assignees":[],"milestone":null,"comments":14,"created_at":"2014-08-08T17:21:40Z","updated_at":"2020-05-09T10:48:24Z","closed_at":"2016-07-21T21:06:50Z","author_association":"NONE","active_lock_reason":null,"body":"In the following code I am not getting the auto complete suggestions for all of Model.Objects. When I use Pycharm it shows the auto complete, So I am not sure why I don't see it with jedi-vim. Here is an example image of pycharm on top and vim on bottom. http://i.imgur.com/pwWl7UK.png\n\nfrom django.db import models\nclass Apple(models.Model):\n    name = models.CharField(max_length=30)\n\nclass Orange(models.Model):\n    name = models.CharField(max_length=30)\n\n```\ndef get_top_apple(self):\n    #I want .objects to autocomplete\n    return Apple.objects.first()\n```\n","performed_via_github_app":null,"score":1.0},{"url":"https://api.github.com/repos/pyinstaller/pyinstaller/issues/4334","repository_url":"https://api.github.com/repos/pyinstaller/pyinstaller","labels_url":"https://api.github.com/repos/pyinstaller/pyinstaller/issues/4334/labels{/name}","comments_url":"https://api.github.com/repos/pyinstaller/pyinstaller/issues/4334/comments","events_url":"https://api.github.com/repos/pyinstaller/pyinstaller/issues/4334/events","html_url":"https://github.com/pyinstaller/pyinstaller/issues/4334","id":472950100,"node_id":"MDU6SXNzdWU0NzI5NTAxMDA=","number":4334,"title":"Tkinter app on macOS 10.14.6 causes WindowServer event port death","user":{"login":"peterruhl","id":53302283,"node_id":"MDQ6VXNlcjUzMzAyMjgz","avatar_url":"https://avatars3.githubusercontent.com/u/53302283?v=4","gravatar_id":"","url":"https://api.github.com/users/peterruhl","html_url":"https://github.com/peterruhl","followers_url":"https://api.github.com/users/peterruhl/followers","following_url":"https://api.github.com/users/peterruhl/following{/other_user}","gists_url":"https://api.github.com/users/peterruhl/gists{/gist_id}","starred_url":"https://api.github.com/users/peterruhl/starred{/owner}{/repo}","subscriptions_url":"https://api.github.com/users/peterruhl/subscriptions","organizations_url":"https://api.github.com/users/peterruhl/orgs","repos_url":"https://api.github.com/users/peterruhl/repos","events_url":"https://api.github.com/users/peterruhl/events{/privacy}","received_events_url":"https://api.github.com/users/peterruhl/received_events","type":"User","site_admin":false},"labels":[{"id":147207830,"node_id":"MDU6TGFiZWwxNDcyMDc4MzA=","url":"https://api.github.com/repos/pyinstaller/pyinstaller/labels/platform:OS%20X","name":"platform:OS X","color":"d4c5f9","default":false,"description":""}],"state":"closed","locked":false,"assignee":null,"assignees":[],"milestone":null,"comments":38,"created_at":"2019-07-25T16:05:43Z","updated_at":"2020-07-07T15:13:29Z","closed_at":"2019-11-16T12:29:00Z","author_association":"NONE","active_lock_reason":null,"body":"**OS: macOS 10.14.6\r\nPython: 3.6.6, 3.6.8, 3.7.4\r\nTkinter: 8.6 (bundled with python)\r\nPyinstaller: 3.5**\r\n\r\nOn macOS 10.14.6, when trying to run any python application using Tkinter that has been frozen, my WindowServer crashes, and brings me back to the macOS login screen. \r\nNo issues while following the same procedure on macOS 10.14.5.\r\n\r\nThe minimum code to reproduce (found below) runs fine on its own on macOS 10.14.6\r\n\r\nI have tried both methods found here: #3753  to ensure that TKinter is included.\r\n\r\nI tried a number of different commands to freeze my application, all producing the same crash. Most recent command was `pyinstaller --windowed myapp.py` as suggested in issue #3753 \r\n\r\nOutput:\r\n\r\n```\r\n2019-07-25 09:30:21.328 Main[3268:17227] CGSTrackingRegionSetIsEnabled returned CG error 268435459\r\n2019-07-25 09:30:21.328 Main[3268:17227] CGSTrackingRegionSetIsEnabled returned CG error 268435459\r\n2019-07-25 09:30:21.328 Main[3268:17227] CGSTrackingRegionSetIsEnabled returned CG error 268435459\r\n2019-07-25 09:30:21.328 Main[3268:17227] CGSTrackingRegionSetIsEnabled returned CG error 268435459\r\n2019-07-25 09:30:21.329 Main[3268:17227] CGSTrackingRegionSetIsEnabled returned CG error 268435459\r\n2019-07-25 09:30:21.329 Main[3268:17227] CGSTrackingRegionSetIsEnabled returned CG error 268435459\r\n2019-07-25 09:30:21.329 Main[3268:17227] CGSTrackingRegionSetIsEnabled returned CG error 268435459\r\n2019-07-25 09:30:21.329 Main[3268:17227] CGSTrackingRegionSetIsEnabled returned CG error 268435459\r\n2019-07-25 09:30:21.329 Main[3268:17227] CGSTrackingRegionSetIsEnabled returned CG error 268435459\r\n2019-07-25 09:30:21.329 Main[3268:17227] CGSTrackingRegionSetIsEnabled returned CG error 268435459\r\n2019-07-25 09:30:21.329 Main[3268:17227] CGSTrackingRegionSetIsEnabled returned CG error 268435459\r\n2019-07-25 09:30:21.329 Main[3268:17227] CGSTrackingRegionSetIsEnabled returned CG error 268435459\r\n2019-07-25 09:30:21.329 Main[3268:17227] CGSTrackingRegionSetIsEnabled returned CG error 268435459\r\n2019-07-25 09:30:21.329 Main[3268:17227] CGSTrackingRegionSetIsEnabled returned CG error 268435459\r\n2019-07-25 09:30:21.329 Main[3268:17227] CGSTrackingRegionSetIsEnabled returned CG error 268435459\r\n2019-07-25 09:30:21.329 Main[3268:17227] CGSTrackingRegionSetIsEnabled returned CG error 268435459\r\n2019-07-25 09:30:21.329 Main[3268:17227] CGSTrackingRegionSetIsEnabled returned CG error 268435459\r\n2019-07-25 09:30:21.329 Main[3268:17227] CGSTrackingRegionSetIsEnabled returned CG error 268435459\r\n2019-07-25 09:30:21.329 Main[3268:17227] CGSTrackingRegionSetIsEnabled returned CG error 268435459\r\n2019-07-25 09:30:21.329 Main[3268:17227] CGSTrackingRegionSetIsEnabled returned CG error 268435459\r\n2019-07-25 09:30:21.329 Main[3268:17227] CGSTrackingRegionSetIsEnabled returned CG error 268435459\r\n2019-07-25 09:30:21.329 Main[3268:17227] CGSTrackingRegionSetIsEnabled returned CG error 268435459\r\n2019-07-25 09:30:21.329 Main[3268:17227] CGSTrackingRegionSetIsEnabled returned CG error 268435459\r\n2019-07-25 09:30:21.329 Main[3268:17227] CGSTrackingRegionSetIsEnabled returned CG error 268435459\r\n2019-07-25 09:30:21.342 Main[3268:17227] HIToolbox: received notification of WindowServer event port death.\r\n2019-07-25 09:30:21.342 Main[3268:17227] port matched the WindowServer port created in BindCGSToRunLoop\r\n```\r\n\r\nMinimum code required to reproduce:\r\n\r\n```\r\n\r\nfrom tkinter import *\r\nclass Main:\r\n    def __init__(self, parent):\r\n\r\n        #Configure the main window\r\n        self.myparent = parent\r\n        self.myparent.wm_title(\"Please Don't Crash\")\r\n        self.myparent.geometry('440x300')\r\n        \r\nroot = Tk()\r\nmyapp = Main(root)\r\nroot.mainloop()\r\n\r\n```\r\n\r\nThis issue was reported on another project that uses pyinstaller as well. https://github.com/nh-server/fusee-interfacee-tk/issues/1","performed_via_github_app":null,"score":1.0},{"url":"https://api.github.com/repos/sahana/eden/issues/1530","repository_url":"https://api.github.com/repos/sahana/eden","labels_url":"https://api.github.com/repos/sahana/eden/issues/1530/labels{/name}","comments_url":"https://api.github.com/repos/sahana/eden/issues/1530/comments","events_url":"https://api.github.com/repos/sahana/eden/issues/1530/events","html_url":"https://github.com/sahana/eden/issues/1530","id":541232311,"node_id":"MDU6SXNzdWU1NDEyMzIzMTE=","number":1530,"title":"SAMBRO cap_info.csv import fails","user":{"login":"trendspotter","id":15286128,"node_id":"MDQ6VXNlcjE1Mjg2MTI4","avatar_url":"https://avatars1.githubusercontent.com/u/15286128?v=4","gravatar_id":"","url":"https://api.github.com/users/trendspotter","html_url":"https://github.com/trendspotter","followers_url":"https://api.github.com/users/trendspotter/followers","following_url":"https://api.github.com/users/trendspotter/following{/other_user}","gists_url":"https://api.github.com/users/trendspotter/gists{/gist_id}","starred_url":"https://api.github.com/users/trendspotter/starred{/owner}{/repo}","subscriptions_url":"https://api.github.com/users/trendspotter/subscriptions","organizations_url":"https://api.github.com/users/trendspotter/orgs","repos_url":"https://api.github.com/users/trendspotter/repos","events_url":"https://api.github.com/users/trendspotter/events{/privacy}","received_events_url":"https://api.github.com/users/trendspotter/received_events","type":"User","site_admin":false},"labels":[{"id":337201926,"node_id":"MDU6TGFiZWwzMzcyMDE5MjY=","url":"https://api.github.com/repos/sahana/eden/labels/Bug","name":"Bug","color":"fbca04","default":false,"description":null},{"id":1697849815,"node_id":"MDU6TGFiZWwxNjk3ODQ5ODE1","url":"https://api.github.com/repos/sahana/eden/labels/CRITICAL","name":"CRITICAL","color":"d31989","default":false,"description":"Critical Issue"},{"id":337204437,"node_id":"MDU6TGFiZWwzMzcyMDQ0Mzc=","url":"https://api.github.com/repos/sahana/eden/labels/Core","name":"Core","color":"207de5","default":false,"description":null}],"state":"closed","locked":false,"assignee":null,"assignees":[],"milestone":null,"comments":8,"created_at":"2019-12-20T22:43:15Z","updated_at":"2019-12-23T11:13:01Z","closed_at":"2019-12-23T11:13:01Z","author_association":"CONTRIBUTOR","active_lock_reason":null,"body":"**Steps to reproduce:**\r\nPerform a clean installation of SAMBRO template including the demo data.\r\n\r\n**Expected result:**\r\nInstallation succeeds.\r\n\r\n**Actual result:**\r\nInstallation fails while importing *cap_info.csv*\r\n```\r\nTraceback (most recent call last):\r\n  File \"/srv/web2py/gluon/restricted.py\", line 219, in restricted\r\n    exec(ccode, environment)\r\n  File \"applications/eden/models/zzz_1st_run.py\", line 319, in <module>\r\n    bi.perform_tasks(path)\r\n  File \"applications/eden/modules/s3/s3import.py\", line 5032, in perform_tasks\r\n    self.execute_import_task(task)\r\n  File \"applications/eden/modules/s3/s3import.py\", line 4353, in execute_import_task\r\n    extra_data=extra_data,\r\n  File \"applications/eden/modules/s3/s3resource.py\", line 2492, in import_xml\r\n    onconflict=onconflict)\r\n  File \"applications/eden/modules/s3/s3resource.py\", line 2724, in import_tree\r\n    log_items = self.get_config(\"oncommit_import_item\"))\r\n  File \"applications/eden/modules/s3/s3import.py\", line 3614, in commit\r\n    success = item.commit(ignore_errors=ignore_errors)\r\n  File \"applications/eden/modules/s3/s3import.py\", line 2544, in commit\r\n    callback(onaccept, form, tablename=tablename)\r\n  File \"/srv/web2py/gluon/tools.py\", line 81, in callback\r\n    [action(form) for action in actions]\r\n  File \"applications/eden/modules/s3db/cap.py\", line 1521, in info_onaccept\r\n    update[\"event\"] = itable.event_type_id.represent(info.event_type_id)\r\n  File \"applications/eden/modules/s3/s3fields.py\", line 454, in __call__\r\n    items = self._lookup([value], rows=rows)\r\n  File \"applications/eden/modules/s3/s3fields.py\", line 772, in _lookup\r\n    items[keys.get(k, k)] = theset[k] = represent_row(row)\r\n  File \"applications/eden/modules/s3/s3fields.py\", line 377, in represent_row\r\n    values = [row[f] for f in self.fields if row[f] not in (None, \"\")]\r\n  File \"/srv/web2py/gluon/packages/dal/pydal/objects.py\", line 94, in __getitem__\r\n    raise KeyError(key)\r\nKeyError: 'name'\r\n```\r\n\r\n**Additional notes:**\r\nWe've initially though that it's because of the malformed data, but it happens also with the corrected CSVs from #1529 (actually any single record is enough to trigger it).\r\n\r\nAlso, we're still using python 2.7, planning to upgrade i the upcoming week. It doesn't seem like the problem is caused by it, but I'm mentioning it just in case.","performed_via_github_app":null,"score":1.0}]}
0

